{
 "cells": [
  {
   "cell_type": "markdown",
   "metadata": {},
   "source": [
    "<h3>Import packages</h3>"
   ]
  },
  {
   "cell_type": "code",
   "execution_count": 1,
   "metadata": {},
   "outputs": [],
   "source": [
    "from datetime import date\n",
    "from timeit import default_timer as timer\n",
    "import numpy as np\n",
    "import tensorflow as tf\n",
    "from tensorflow import keras\n",
    "from tensorflow.keras import layers\n",
    "from tensorflow.keras.layers import Dense, Activation, Dropout\n",
    "from tensorflow.keras.optimizers import Adam\n",
    "from tensorflow.keras.metrics import categorical_crossentropy\n",
    "from tensorflow.keras.preprocessing.image import ImageDataGenerator, load_img\n",
    "# from keras.applications.resnet50 import preprocess_input\n",
    "from tensorflow.keras.preprocessing import image\n",
    "from tensorflow.keras.models import Model, Sequential\n",
    "from tensorflow.keras.applications import imagenet_utils\n",
    "from keras.callbacks import EarlyStopping\n",
    "from sklearn.metrics import confusion_matrix, classification_report\n",
    "import itertools\n",
    "import os\n",
    "import shutil\n",
    "import random\n",
    "import matplotlib.pyplot as plt\n",
    "%matplotlib inline"
   ]
  },
  {
   "cell_type": "code",
   "execution_count": 2,
   "metadata": {},
   "outputs": [
    {
     "name": "stdout",
     "output_type": "stream",
     "text": [
      "Num GPUs Available:  1\n"
     ]
    }
   ],
   "source": [
    "#Configure TensorFlow to use GPU for training\n",
    "tf.config.list_physical_devices('GPU') \n",
    "print(\"Num GPUs Available: \", len(tf.config.list_physical_devices('GPU')))\n",
    "\n",
    "gpus = tf.config.experimental.list_physical_devices('GPU')\n",
    "#Set GPU memory limit so my GPU doesn't crash\n",
    "if gpus:\n",
    "    try:\n",
    "        for gpu in gpus:\n",
    "              tf.config.experimental.set_memory_growth(gpu, True)\n",
    "    except RuntimeError as e:\n",
    "        print(e)"
   ]
  },
  {
   "cell_type": "markdown",
   "metadata": {},
   "source": [
    "<h3>Create class to record time taken to train the model</h3>"
   ]
  },
  {
   "cell_type": "code",
   "execution_count": 3,
   "metadata": {},
   "outputs": [],
   "source": [
    "#class to record time taken to train per epoch\n",
    "class TimingCallback(keras.callbacks.Callback):\n",
    "    def __init__(self, logs={}):\n",
    "        self.logs=[]\n",
    "    def on_epoch_begin(self, epoch, logs={}):\n",
    "        self.starttime = timer()\n",
    "    def on_epoch_end(self, epoch, logs={}):\n",
    "        self.logs.append(timer()-self.starttime)\n",
    "\n",
    "cb = TimingCallback()"
   ]
  },
  {
   "cell_type": "markdown",
   "metadata": {},
   "source": [
    "<h3>Create train and test folder</h3>"
   ]
  },
  {
   "cell_type": "code",
   "execution_count": 4,
   "metadata": {},
   "outputs": [],
   "source": [
    "#creates a folder each time the set of code is run to sort dataset into train and test\n",
    "day = date.today()\n",
    "formatDate = day.strftime(\"%b-%d-%Y\")\n",
    "\n",
    "#create folder with current date to group predictions ran in a day together, if it does not exists\n",
    "if os.path.isdir('Prediction (' + formatDate + ')') is False:\n",
    "    folder = os.mkdir('Prediction (' + formatDate + ')')\n",
    "folder = 'Prediction (' + formatDate + ')'\n",
    "\n",
    "#looping through to find if destination folder exists\n",
    "i = 1\n",
    "while True:\n",
    "    if os.path.isdir(folder + '/dataset_6 - ' + str(i)) is False:\n",
    "        break\n",
    "    i += 1\n",
    "\n",
    "#destination path for unsorted folder\n",
    "destination = folder + '/dataset_6 - ' + str(i)\n",
    "\n",
    "#source path for unsorted folder\n",
    "source = 'dataset_6/'\n",
    "\n",
    "#duplicate the unsorted folder from source to destination\n",
    "shutil.copytree(source, destination)\n",
    "\n",
    "os.mkdir(destination + '/train')\n",
    "os.mkdir(destination + '/test')"
   ]
  },
  {
   "cell_type": "markdown",
   "metadata": {},
   "source": [
    "<h3>Sort dataset into train and test folder</h3>"
   ]
  },
  {
   "cell_type": "code",
   "execution_count": 5,
   "metadata": {},
   "outputs": [],
   "source": [
    "#function to split images into training (80%) and testing (20%) and return both\n",
    "def split(data):\n",
    "    num = int(len(data) * 0.8)\n",
    "    # num = int(len(data) * 0.9) #90/10 split\n",
    "#     num = int(len(data) * 0.7) #70/30 split\n",
    "    random.shuffle(data)\n",
    "    return data[:num], data[num:]\n",
    "\n",
    "dir = os.chdir(destination)\n",
    "for category in os.listdir(dir):\n",
    "    #skip the iteration if folder is \"train\" or \"test\"\n",
    "    skip = ['train', 'test']\n",
    "    if category in skip:\n",
    "        continue\n",
    "    \n",
    "    shutil.move(f'{category}', 'train')\n",
    "    #create a subfolder with the same name in test\n",
    "    os.mkdir(f'test/{category}')\n",
    "\n",
    "    #get the images in each folder (battery type) for spltting of data into training and testing\n",
    "    img = os.listdir(f'train/{category}')\n",
    "    training, testing = split(img)\n",
    "    \n",
    "    for file in testing:\n",
    "        shutil.move(f'train/{category}/{file}', f'test/{category}')"
   ]
  },
  {
   "cell_type": "markdown",
   "metadata": {},
   "source": [
    "<h3>Transfer Learning</h3>"
   ]
  },
  {
   "cell_type": "code",
   "execution_count": 6,
   "metadata": {},
   "outputs": [],
   "source": [
    "#\"include_top=False argument\" will load a network that excluding the classification layers at the top\n",
    "mobile = tf.keras.applications.VGG19(input_shape = (224, 224, 3), include_top = False, weights = \"imagenet\")"
   ]
  },
  {
   "cell_type": "code",
   "execution_count": 7,
   "metadata": {
    "scrolled": true
   },
   "outputs": [
    {
     "name": "stdout",
     "output_type": "stream",
     "text": [
      "Model: \"vgg19\"\n",
      "_________________________________________________________________\n",
      " Layer (type)                Output Shape              Param #   \n",
      "=================================================================\n",
      " input_1 (InputLayer)        [(None, 224, 224, 3)]     0         \n",
      "                                                                 \n",
      " block1_conv1 (Conv2D)       (None, 224, 224, 64)      1792      \n",
      "                                                                 \n",
      " block1_conv2 (Conv2D)       (None, 224, 224, 64)      36928     \n",
      "                                                                 \n",
      " block1_pool (MaxPooling2D)  (None, 112, 112, 64)      0         \n",
      "                                                                 \n",
      " block2_conv1 (Conv2D)       (None, 112, 112, 128)     73856     \n",
      "                                                                 \n",
      " block2_conv2 (Conv2D)       (None, 112, 112, 128)     147584    \n",
      "                                                                 \n",
      " block2_pool (MaxPooling2D)  (None, 56, 56, 128)       0         \n",
      "                                                                 \n",
      " block3_conv1 (Conv2D)       (None, 56, 56, 256)       295168    \n",
      "                                                                 \n",
      " block3_conv2 (Conv2D)       (None, 56, 56, 256)       590080    \n",
      "                                                                 \n",
      " block3_conv3 (Conv2D)       (None, 56, 56, 256)       590080    \n",
      "                                                                 \n",
      " block3_conv4 (Conv2D)       (None, 56, 56, 256)       590080    \n",
      "                                                                 \n",
      " block3_pool (MaxPooling2D)  (None, 28, 28, 256)       0         \n",
      "                                                                 \n",
      " block4_conv1 (Conv2D)       (None, 28, 28, 512)       1180160   \n",
      "                                                                 \n",
      " block4_conv2 (Conv2D)       (None, 28, 28, 512)       2359808   \n",
      "                                                                 \n",
      " block4_conv3 (Conv2D)       (None, 28, 28, 512)       2359808   \n",
      "                                                                 \n",
      " block4_conv4 (Conv2D)       (None, 28, 28, 512)       2359808   \n",
      "                                                                 \n",
      " block4_pool (MaxPooling2D)  (None, 14, 14, 512)       0         \n",
      "                                                                 \n",
      " block5_conv1 (Conv2D)       (None, 14, 14, 512)       2359808   \n",
      "                                                                 \n",
      " block5_conv2 (Conv2D)       (None, 14, 14, 512)       2359808   \n",
      "                                                                 \n",
      " block5_conv3 (Conv2D)       (None, 14, 14, 512)       2359808   \n",
      "                                                                 \n",
      " block5_conv4 (Conv2D)       (None, 14, 14, 512)       2359808   \n",
      "                                                                 \n",
      " block5_pool (MaxPooling2D)  (None, 7, 7, 512)         0         \n",
      "                                                                 \n",
      "=================================================================\n",
      "Total params: 20,024,384\n",
      "Trainable params: 20,024,384\n",
      "Non-trainable params: 0\n",
      "_________________________________________________________________\n"
     ]
    }
   ],
   "source": [
    "mobile.summary()"
   ]
  },
  {
   "cell_type": "code",
   "execution_count": 8,
   "metadata": {
    "scrolled": true
   },
   "outputs": [
    {
     "name": "stdout",
     "output_type": "stream",
     "text": [
      "Model: \"model\"\n",
      "_________________________________________________________________\n",
      " Layer (type)                Output Shape              Param #   \n",
      "=================================================================\n",
      " input_2 (InputLayer)        [(None, 224, 224, 3)]     0         \n",
      "                                                                 \n",
      " vgg19 (Functional)          (None, 7, 7, 512)         20024384  \n",
      "                                                                 \n",
      " global_average_pooling2d (G  (None, 512)              0         \n",
      " lobalAveragePooling2D)                                          \n",
      "                                                                 \n",
      " dropout (Dropout)           (None, 512)               0         \n",
      "                                                                 \n",
      " dense (Dense)               (None, 1)                 513       \n",
      "                                                                 \n",
      "=================================================================\n",
      "Total params: 20,024,897\n",
      "Trainable params: 2,360,321\n",
      "Non-trainable params: 17,664,576\n",
      "_________________________________________________________________\n"
     ]
    }
   ],
   "source": [
    "for layer in mobile.layers[:-2]:\n",
    "    layer.trainable = False\n",
    "\n",
    "inputs = keras.Input(shape=(224, 224, 3))\n",
    "x = mobile(inputs, training=False)\n",
    "x = tf.keras.layers.GlobalAveragePooling2D()(x)\n",
    "x = tf.keras.layers.Dropout(0.5)(x)\n",
    "output = tf.keras.layers.Dense(1, activation=\"sigmoid\")(x)  \n",
    "\n",
    "model = keras.Model(inputs, output)\n",
    "\n",
    "model.summary()"
   ]
  },
  {
   "cell_type": "markdown",
   "metadata": {},
   "source": [
    "<h3>Process data</h3>"
   ]
  },
  {
   "cell_type": "code",
   "execution_count": 9,
   "metadata": {},
   "outputs": [
    {
     "name": "stdout",
     "output_type": "stream",
     "text": [
      "Found 276 images belonging to 2 classes.\n",
      "Found 68 images belonging to 2 classes.\n",
      "Found 86 images belonging to 2 classes.\n"
     ]
    }
   ],
   "source": [
    "train_path = 'train'\n",
    "test_path = 'test'\n",
    "\n",
    "#for data augmentation on training data\n",
    "datagen = ImageDataGenerator( \n",
    "    preprocessing_function =tf.keras.applications.resnet50.preprocess_input,\n",
    "    validation_split=0.2,\n",
    "    # validation_split=0.1, #changes made for 90/10 split\n",
    "    rotation_range = 10,  # randomly rotate images in the range (degrees, 0 to 180)\n",
    "    zoom_range = 0.2, # Randomly zoom image \n",
    "    width_shift_range = 0.1,  # randomly shift images horizontally (fraction of total width)\n",
    "    height_shift_range = 0.1,  # randomly shift images vertically (fraction of total height)\n",
    "    horizontal_flip = True,  # randomly flip images\n",
    "#     vertical_flip = False,    # randomly flip images\n",
    "    vertical_flip = True, #include vertical flip for better generalisation\n",
    "    )  \n",
    "\n",
    "#takes images from directory path and generates batches of augmented data\n",
    "train = datagen.flow_from_directory(\n",
    "    directory=train_path,\n",
    "    target_size=(224, 224),\n",
    "    class_mode = 'binary',\n",
    "    batch_size=32,\n",
    "    subset='training',\n",
    "        shuffle = False)\n",
    "\n",
    "#for validation data\n",
    "validation_batches = ImageDataGenerator(preprocessing_function=tf.keras.applications.resnet50.preprocess_input, \n",
    "                                        validation_split=0.2)\n",
    "# validation_batches = ImageDataGenerator(preprocessing_function=tf.keras.applications.mobilenet.preprocess_input, \n",
    "#                                         validation_split=0.1) #changes made for 90/10 split\n",
    "\n",
    "\n",
    "validation = validation_batches.flow_from_directory(\n",
    "    directory=train_path,\n",
    "    target_size=(224, 224),\n",
    "    class_mode = 'binary',\n",
    "    batch_size=32,\n",
    "    subset='validation',\n",
    "        shuffle = False)\n",
    "\n",
    "#for test data\n",
    "test = ImageDataGenerator(preprocessing_function=tf.keras.applications.resnet50.preprocess_input)\\\n",
    ".flow_from_directory(directory=test_path, target_size=(224,224), class_mode = 'binary', batch_size=32, shuffle=False)"
   ]
  },
  {
   "cell_type": "markdown",
   "metadata": {},
   "source": [
    "<h3>Train model</h3>"
   ]
  },
  {
   "cell_type": "code",
   "execution_count": 10,
   "metadata": {
    "scrolled": true
   },
   "outputs": [
    {
     "name": "stdout",
     "output_type": "stream",
     "text": [
      "Epoch 1/150\n",
      "Unexpected exception formatting exception. Falling back to standard exception\n"
     ]
    },
    {
     "name": "stderr",
     "output_type": "stream",
     "text": [
      "Traceback (most recent call last):\n",
      "  File \"C:\\Users\\ngden\\AppData\\Roaming\\Python\\Python310\\site-packages\\IPython\\core\\interactiveshell.py\", line 3508, in run_code\n",
      "    exec(code_obj, self.user_global_ns, self.user_ns)\n",
      "  File \"C:\\Users\\ngden\\AppData\\Local\\Temp\\ipykernel_728\\1895632919.py\", line 14, in <module>\n",
      "    result = model.fit(x=train, validation_data=validation, epochs=150, verbose=2, callbacks=[model_checkpoint_callback,cb])\n",
      "  File \"c:\\Users\\ngden\\anaconda3\\lib\\site-packages\\keras\\utils\\traceback_utils.py\", line 70, in error_handler\n",
      "    raise e.with_traceback(filtered_tb) from None\n",
      "  File \"c:\\Users\\ngden\\anaconda3\\lib\\site-packages\\tensorflow\\python\\eager\\execute.py\", line 54, in quick_execute\n",
      "    tensors = pywrap_tfe.TFE_Py_Execute(ctx._handle, device_name, op_name,\n",
      "tensorflow.python.framework.errors_impl.ResourceExhaustedError: Graph execution error:\n",
      "\n",
      "Detected at node 'model/vgg19/block1_conv2/Relu' defined at (most recent call last):\n",
      "    File \"c:\\Users\\ngden\\anaconda3\\lib\\runpy.py\", line 196, in _run_module_as_main\n",
      "      return _run_code(code, main_globals, None,\n",
      "    File \"c:\\Users\\ngden\\anaconda3\\lib\\runpy.py\", line 86, in _run_code\n",
      "      exec(code, run_globals)\n",
      "    File \"C:\\Users\\ngden\\AppData\\Roaming\\Python\\Python310\\site-packages\\ipykernel_launcher.py\", line 17, in <module>\n",
      "      app.launch_new_instance()\n",
      "    File \"C:\\Users\\ngden\\AppData\\Roaming\\Python\\Python310\\site-packages\\traitlets\\config\\application.py\", line 1043, in launch_instance\n",
      "      app.start()\n",
      "    File \"C:\\Users\\ngden\\AppData\\Roaming\\Python\\Python310\\site-packages\\ipykernel\\kernelapp.py\", line 728, in start\n",
      "      self.io_loop.start()\n",
      "    File \"C:\\Users\\ngden\\AppData\\Roaming\\Python\\Python310\\site-packages\\tornado\\platform\\asyncio.py\", line 195, in start\n",
      "      self.asyncio_loop.run_forever()\n",
      "    File \"c:\\Users\\ngden\\anaconda3\\lib\\asyncio\\base_events.py\", line 603, in run_forever\n",
      "      self._run_once()\n",
      "    File \"c:\\Users\\ngden\\anaconda3\\lib\\asyncio\\base_events.py\", line 1906, in _run_once\n",
      "      handle._run()\n",
      "    File \"c:\\Users\\ngden\\anaconda3\\lib\\asyncio\\events.py\", line 80, in _run\n",
      "      self._context.run(self._callback, *self._args)\n",
      "    File \"C:\\Users\\ngden\\AppData\\Roaming\\Python\\Python310\\site-packages\\ipykernel\\kernelbase.py\", line 516, in dispatch_queue\n",
      "      await self.process_one()\n",
      "    File \"C:\\Users\\ngden\\AppData\\Roaming\\Python\\Python310\\site-packages\\ipykernel\\kernelbase.py\", line 505, in process_one\n",
      "      await dispatch(*args)\n",
      "    File \"C:\\Users\\ngden\\AppData\\Roaming\\Python\\Python310\\site-packages\\ipykernel\\kernelbase.py\", line 412, in dispatch_shell\n",
      "      await result\n",
      "    File \"C:\\Users\\ngden\\AppData\\Roaming\\Python\\Python310\\site-packages\\ipykernel\\kernelbase.py\", line 740, in execute_request\n",
      "      reply_content = await reply_content\n",
      "    File \"C:\\Users\\ngden\\AppData\\Roaming\\Python\\Python310\\site-packages\\ipykernel\\ipkernel.py\", line 422, in do_execute\n",
      "      res = shell.run_cell(\n",
      "    File \"C:\\Users\\ngden\\AppData\\Roaming\\Python\\Python310\\site-packages\\ipykernel\\zmqshell.py\", line 540, in run_cell\n",
      "      return super().run_cell(*args, **kwargs)\n",
      "    File \"C:\\Users\\ngden\\AppData\\Roaming\\Python\\Python310\\site-packages\\IPython\\core\\interactiveshell.py\", line 3009, in run_cell\n",
      "      result = self._run_cell(\n",
      "    File \"C:\\Users\\ngden\\AppData\\Roaming\\Python\\Python310\\site-packages\\IPython\\core\\interactiveshell.py\", line 3064, in _run_cell\n",
      "      result = runner(coro)\n",
      "    File \"C:\\Users\\ngden\\AppData\\Roaming\\Python\\Python310\\site-packages\\IPython\\core\\async_helpers.py\", line 129, in _pseudo_sync_runner\n",
      "      coro.send(None)\n",
      "    File \"C:\\Users\\ngden\\AppData\\Roaming\\Python\\Python310\\site-packages\\IPython\\core\\interactiveshell.py\", line 3269, in run_cell_async\n",
      "      has_raised = await self.run_ast_nodes(code_ast.body, cell_name,\n",
      "    File \"C:\\Users\\ngden\\AppData\\Roaming\\Python\\Python310\\site-packages\\IPython\\core\\interactiveshell.py\", line 3448, in run_ast_nodes\n",
      "      if await self.run_code(code, result, async_=asy):\n",
      "    File \"C:\\Users\\ngden\\AppData\\Roaming\\Python\\Python310\\site-packages\\IPython\\core\\interactiveshell.py\", line 3508, in run_code\n",
      "      exec(code_obj, self.user_global_ns, self.user_ns)\n",
      "    File \"C:\\Users\\ngden\\AppData\\Local\\Temp\\ipykernel_728\\1895632919.py\", line 14, in <module>\n",
      "      result = model.fit(x=train, validation_data=validation, epochs=150, verbose=2, callbacks=[model_checkpoint_callback,cb])\n",
      "    File \"c:\\Users\\ngden\\anaconda3\\lib\\site-packages\\keras\\utils\\traceback_utils.py\", line 65, in error_handler\n",
      "      return fn(*args, **kwargs)\n",
      "    File \"c:\\Users\\ngden\\anaconda3\\lib\\site-packages\\keras\\engine\\training.py\", line 1564, in fit\n",
      "      tmp_logs = self.train_function(iterator)\n",
      "    File \"c:\\Users\\ngden\\anaconda3\\lib\\site-packages\\keras\\engine\\training.py\", line 1160, in train_function\n",
      "      return step_function(self, iterator)\n",
      "    File \"c:\\Users\\ngden\\anaconda3\\lib\\site-packages\\keras\\engine\\training.py\", line 1146, in step_function\n",
      "      outputs = model.distribute_strategy.run(run_step, args=(data,))\n",
      "    File \"c:\\Users\\ngden\\anaconda3\\lib\\site-packages\\keras\\engine\\training.py\", line 1135, in run_step\n",
      "      outputs = model.train_step(data)\n",
      "    File \"c:\\Users\\ngden\\anaconda3\\lib\\site-packages\\keras\\engine\\training.py\", line 993, in train_step\n",
      "      y_pred = self(x, training=True)\n",
      "    File \"c:\\Users\\ngden\\anaconda3\\lib\\site-packages\\keras\\utils\\traceback_utils.py\", line 65, in error_handler\n",
      "      return fn(*args, **kwargs)\n",
      "    File \"c:\\Users\\ngden\\anaconda3\\lib\\site-packages\\keras\\engine\\training.py\", line 557, in __call__\n",
      "      return super().__call__(*args, **kwargs)\n",
      "    File \"c:\\Users\\ngden\\anaconda3\\lib\\site-packages\\keras\\utils\\traceback_utils.py\", line 65, in error_handler\n",
      "      return fn(*args, **kwargs)\n",
      "    File \"c:\\Users\\ngden\\anaconda3\\lib\\site-packages\\keras\\engine\\base_layer.py\", line 1097, in __call__\n",
      "      outputs = call_fn(inputs, *args, **kwargs)\n",
      "    File \"c:\\Users\\ngden\\anaconda3\\lib\\site-packages\\keras\\utils\\traceback_utils.py\", line 96, in error_handler\n",
      "      return fn(*args, **kwargs)\n",
      "    File \"c:\\Users\\ngden\\anaconda3\\lib\\site-packages\\keras\\engine\\functional.py\", line 510, in call\n",
      "      return self._run_internal_graph(inputs, training=training, mask=mask)\n",
      "    File \"c:\\Users\\ngden\\anaconda3\\lib\\site-packages\\keras\\engine\\functional.py\", line 667, in _run_internal_graph\n",
      "      outputs = node.layer(*args, **kwargs)\n",
      "    File \"c:\\Users\\ngden\\anaconda3\\lib\\site-packages\\keras\\utils\\traceback_utils.py\", line 65, in error_handler\n",
      "      return fn(*args, **kwargs)\n",
      "    File \"c:\\Users\\ngden\\anaconda3\\lib\\site-packages\\keras\\engine\\training.py\", line 557, in __call__\n",
      "      return super().__call__(*args, **kwargs)\n",
      "    File \"c:\\Users\\ngden\\anaconda3\\lib\\site-packages\\keras\\utils\\traceback_utils.py\", line 65, in error_handler\n",
      "      return fn(*args, **kwargs)\n",
      "    File \"c:\\Users\\ngden\\anaconda3\\lib\\site-packages\\keras\\engine\\base_layer.py\", line 1097, in __call__\n",
      "      outputs = call_fn(inputs, *args, **kwargs)\n",
      "    File \"c:\\Users\\ngden\\anaconda3\\lib\\site-packages\\keras\\utils\\traceback_utils.py\", line 96, in error_handler\n",
      "      return fn(*args, **kwargs)\n",
      "    File \"c:\\Users\\ngden\\anaconda3\\lib\\site-packages\\keras\\engine\\functional.py\", line 510, in call\n",
      "      return self._run_internal_graph(inputs, training=training, mask=mask)\n",
      "    File \"c:\\Users\\ngden\\anaconda3\\lib\\site-packages\\keras\\engine\\functional.py\", line 667, in _run_internal_graph\n",
      "      outputs = node.layer(*args, **kwargs)\n",
      "    File \"c:\\Users\\ngden\\anaconda3\\lib\\site-packages\\keras\\utils\\traceback_utils.py\", line 65, in error_handler\n",
      "      return fn(*args, **kwargs)\n",
      "    File \"c:\\Users\\ngden\\anaconda3\\lib\\site-packages\\keras\\engine\\base_layer.py\", line 1097, in __call__\n",
      "      outputs = call_fn(inputs, *args, **kwargs)\n",
      "    File \"c:\\Users\\ngden\\anaconda3\\lib\\site-packages\\keras\\utils\\traceback_utils.py\", line 96, in error_handler\n",
      "      return fn(*args, **kwargs)\n",
      "    File \"c:\\Users\\ngden\\anaconda3\\lib\\site-packages\\keras\\layers\\convolutional\\base_conv.py\", line 314, in call\n",
      "      return self.activation(outputs)\n",
      "    File \"c:\\Users\\ngden\\anaconda3\\lib\\site-packages\\keras\\activations.py\", line 317, in relu\n",
      "      return backend.relu(\n",
      "    File \"c:\\Users\\ngden\\anaconda3\\lib\\site-packages\\keras\\backend.py\", line 5366, in relu\n",
      "      x = tf.nn.relu(x)\n",
      "Node: 'model/vgg19/block1_conv2/Relu'\n",
      "OOM when allocating tensor with shape[32,64,224,224] and type float on /job:localhost/replica:0/task:0/device:GPU:0 by allocator GPU_0_bfc\n",
      "\t [[{{node model/vgg19/block1_conv2/Relu}}]]\n",
      "Hint: If you want to see a list of allocated tensors when OOM happens, add report_tensor_allocations_upon_oom to RunOptions for current allocation info. This isn't available when running in Eager mode.\n",
      " [Op:__inference_train_function_1750]\n",
      "\n",
      "During handling of the above exception, another exception occurred:\n",
      "\n",
      "Traceback (most recent call last):\n",
      "  File \"C:\\Users\\ngden\\AppData\\Roaming\\Python\\Python310\\site-packages\\IPython\\core\\interactiveshell.py\", line 2105, in showtraceback\n",
      "    stb = self.InteractiveTB.structured_traceback(\n",
      "  File \"C:\\Users\\ngden\\AppData\\Roaming\\Python\\Python310\\site-packages\\IPython\\core\\ultratb.py\", line 1428, in structured_traceback\n",
      "    return FormattedTB.structured_traceback(\n",
      "  File \"C:\\Users\\ngden\\AppData\\Roaming\\Python\\Python310\\site-packages\\IPython\\core\\ultratb.py\", line 1319, in structured_traceback\n",
      "    return VerboseTB.structured_traceback(\n",
      "  File \"C:\\Users\\ngden\\AppData\\Roaming\\Python\\Python310\\site-packages\\IPython\\core\\ultratb.py\", line 1172, in structured_traceback\n",
      "    formatted_exception = self.format_exception_as_a_whole(etype, evalue, etb, number_of_lines_of_context,\n",
      "  File \"C:\\Users\\ngden\\AppData\\Roaming\\Python\\Python310\\site-packages\\IPython\\core\\ultratb.py\", line 1087, in format_exception_as_a_whole\n",
      "    frames.append(self.format_record(record))\n",
      "  File \"C:\\Users\\ngden\\AppData\\Roaming\\Python\\Python310\\site-packages\\IPython\\core\\ultratb.py\", line 969, in format_record\n",
      "    frame_info.lines, Colors, self.has_colors, lvals\n",
      "  File \"C:\\Users\\ngden\\AppData\\Roaming\\Python\\Python310\\site-packages\\IPython\\core\\ultratb.py\", line 792, in lines\n",
      "    return self._sd.lines\n",
      "  File \"C:\\Users\\ngden\\AppData\\Roaming\\Python\\Python310\\site-packages\\stack_data\\utils.py\", line 144, in cached_property_wrapper\n",
      "    value = obj.__dict__[self.func.__name__] = self.func(obj)\n",
      "  File \"C:\\Users\\ngden\\AppData\\Roaming\\Python\\Python310\\site-packages\\stack_data\\core.py\", line 734, in lines\n",
      "    pieces = self.included_pieces\n",
      "  File \"C:\\Users\\ngden\\AppData\\Roaming\\Python\\Python310\\site-packages\\stack_data\\utils.py\", line 144, in cached_property_wrapper\n",
      "    value = obj.__dict__[self.func.__name__] = self.func(obj)\n",
      "  File \"C:\\Users\\ngden\\AppData\\Roaming\\Python\\Python310\\site-packages\\stack_data\\core.py\", line 677, in included_pieces\n",
      "    scope_pieces = self.scope_pieces\n",
      "  File \"C:\\Users\\ngden\\AppData\\Roaming\\Python\\Python310\\site-packages\\stack_data\\utils.py\", line 144, in cached_property_wrapper\n",
      "    value = obj.__dict__[self.func.__name__] = self.func(obj)\n",
      "  File \"C:\\Users\\ngden\\AppData\\Roaming\\Python\\Python310\\site-packages\\stack_data\\core.py\", line 614, in scope_pieces\n",
      "    scope_start, scope_end = self.source.line_range(self.scope)\n",
      "  File \"C:\\Users\\ngden\\AppData\\Roaming\\Python\\Python310\\site-packages\\stack_data\\core.py\", line 178, in line_range\n",
      "    return line_range(self.asttext(), node)\n",
      "AttributeError: 'Source' object has no attribute 'asttext'\n"
     ]
    }
   ],
   "source": [
    "model.compile(optimizer=Adam(learning_rate=0.0006), loss='binary_crossentropy', metrics=['binary_accuracy']) #Last best setting\n",
    "# model.compile(optimizer=Adam(learning_rate=0.006), loss='binary_crossentropy', metrics=['accuracy']) #Last best setting\n",
    "checkpoint_filepath = './tmp/checkpoint'\n",
    "\n",
    "model_checkpoint_callback = tf.keras.callbacks.ModelCheckpoint(\n",
    "    filepath=checkpoint_filepath,\n",
    "    save_weights_only=True,\n",
    "    monitor='val_binary_accuracy',\n",
    "    # monitor='val_accuracy',\n",
    "    mode='max',\n",
    "    save_best_only=True) #save best model\n",
    "\n",
    "#more epochs for better results\n",
    "result = model.fit(x=train, validation_data=validation, epochs=150, verbose=2, callbacks=[model_checkpoint_callback,cb])"
   ]
  },
  {
   "cell_type": "code",
   "execution_count": 11,
   "metadata": {},
   "outputs": [
    {
     "name": "stdout",
     "output_type": "stream",
     "text": [
      "Unexpected exception formatting exception. Falling back to standard exception\n"
     ]
    },
    {
     "name": "stderr",
     "output_type": "stream",
     "text": [
      "Traceback (most recent call last):\n",
      "  File \"C:\\Users\\ngden\\AppData\\Roaming\\Python\\Python310\\site-packages\\IPython\\core\\interactiveshell.py\", line 3508, in run_code\n",
      "    exec(code_obj, self.user_global_ns, self.user_ns)\n",
      "  File \"C:\\Users\\ngden\\AppData\\Local\\Temp\\ipykernel_728\\882731118.py\", line 2, in <module>\n",
      "    plt.plot(result.history['binary_accuracy'])\n",
      "NameError: name 'result' is not defined\n",
      "\n",
      "During handling of the above exception, another exception occurred:\n",
      "\n",
      "Traceback (most recent call last):\n",
      "  File \"C:\\Users\\ngden\\AppData\\Roaming\\Python\\Python310\\site-packages\\IPython\\core\\interactiveshell.py\", line 2105, in showtraceback\n",
      "    stb = self.InteractiveTB.structured_traceback(\n",
      "  File \"C:\\Users\\ngden\\AppData\\Roaming\\Python\\Python310\\site-packages\\IPython\\core\\ultratb.py\", line 1428, in structured_traceback\n",
      "    return FormattedTB.structured_traceback(\n",
      "  File \"C:\\Users\\ngden\\AppData\\Roaming\\Python\\Python310\\site-packages\\IPython\\core\\ultratb.py\", line 1319, in structured_traceback\n",
      "    return VerboseTB.structured_traceback(\n",
      "  File \"C:\\Users\\ngden\\AppData\\Roaming\\Python\\Python310\\site-packages\\IPython\\core\\ultratb.py\", line 1172, in structured_traceback\n",
      "    formatted_exception = self.format_exception_as_a_whole(etype, evalue, etb, number_of_lines_of_context,\n",
      "  File \"C:\\Users\\ngden\\AppData\\Roaming\\Python\\Python310\\site-packages\\IPython\\core\\ultratb.py\", line 1087, in format_exception_as_a_whole\n",
      "    frames.append(self.format_record(record))\n",
      "  File \"C:\\Users\\ngden\\AppData\\Roaming\\Python\\Python310\\site-packages\\IPython\\core\\ultratb.py\", line 969, in format_record\n",
      "    frame_info.lines, Colors, self.has_colors, lvals\n",
      "  File \"C:\\Users\\ngden\\AppData\\Roaming\\Python\\Python310\\site-packages\\IPython\\core\\ultratb.py\", line 792, in lines\n",
      "    return self._sd.lines\n",
      "  File \"C:\\Users\\ngden\\AppData\\Roaming\\Python\\Python310\\site-packages\\stack_data\\utils.py\", line 144, in cached_property_wrapper\n",
      "    value = obj.__dict__[self.func.__name__] = self.func(obj)\n",
      "  File \"C:\\Users\\ngden\\AppData\\Roaming\\Python\\Python310\\site-packages\\stack_data\\core.py\", line 734, in lines\n",
      "    pieces = self.included_pieces\n",
      "  File \"C:\\Users\\ngden\\AppData\\Roaming\\Python\\Python310\\site-packages\\stack_data\\utils.py\", line 144, in cached_property_wrapper\n",
      "    value = obj.__dict__[self.func.__name__] = self.func(obj)\n",
      "  File \"C:\\Users\\ngden\\AppData\\Roaming\\Python\\Python310\\site-packages\\stack_data\\core.py\", line 677, in included_pieces\n",
      "    scope_pieces = self.scope_pieces\n",
      "  File \"C:\\Users\\ngden\\AppData\\Roaming\\Python\\Python310\\site-packages\\stack_data\\utils.py\", line 144, in cached_property_wrapper\n",
      "    value = obj.__dict__[self.func.__name__] = self.func(obj)\n",
      "  File \"C:\\Users\\ngden\\AppData\\Roaming\\Python\\Python310\\site-packages\\stack_data\\core.py\", line 614, in scope_pieces\n",
      "    scope_start, scope_end = self.source.line_range(self.scope)\n",
      "  File \"C:\\Users\\ngden\\AppData\\Roaming\\Python\\Python310\\site-packages\\stack_data\\core.py\", line 178, in line_range\n",
      "    return line_range(self.asttext(), node)\n",
      "AttributeError: 'Source' object has no attribute 'asttext'\n"
     ]
    }
   ],
   "source": [
    "#accuracy\n",
    "plt.plot(result.history['binary_accuracy'])\n",
    "plt.plot(result.history['val_binary_accuracy'])\n",
    "# plt.plot(result.history['accuracy'])\n",
    "# plt.plot(result.history['val_accuracy'])\n",
    "plt.title('model accuracy')\n",
    "plt.ylabel('accuracy')\n",
    "plt.xlabel('epoch')\n",
    "plt.legend(['Train', 'Validation'], loc='lower right')\n",
    "plt.show()\n",
    "\n",
    "#loss\n",
    "plt.plot(result.history['loss'])\n",
    "plt.plot(result.history['val_loss'])\n",
    "plt.title('model loss')\n",
    "plt.ylabel('loss')\n",
    "plt.xlabel('epoch')\n",
    "plt.legend(['Train', 'Validation'], loc='upper right')\n",
    "plt.show()"
   ]
  },
  {
   "cell_type": "code",
   "execution_count": 12,
   "metadata": {},
   "outputs": [
    {
     "name": "stdout",
     "output_type": "stream",
     "text": [
      "Unexpected exception formatting exception. Falling back to standard exception\n"
     ]
    },
    {
     "name": "stderr",
     "output_type": "stream",
     "text": [
      "Traceback (most recent call last):\n",
      "  File \"C:\\Users\\ngden\\AppData\\Roaming\\Python\\Python310\\site-packages\\IPython\\core\\interactiveshell.py\", line 3508, in run_code\n",
      "    exec(code_obj, self.user_global_ns, self.user_ns)\n",
      "  File \"C:\\Users\\ngden\\AppData\\Local\\Temp\\ipykernel_728\\3613985657.py\", line 3, in <module>\n",
      "    result = model.load_weights(checkpoint_filepath)\n",
      "  File \"c:\\Users\\ngden\\anaconda3\\lib\\site-packages\\keras\\utils\\traceback_utils.py\", line 70, in error_handler\n",
      "    raise e.with_traceback(filtered_tb) from None\n",
      "  File \"c:\\Users\\ngden\\anaconda3\\lib\\site-packages\\tensorflow\\python\\training\\py_checkpoint_reader.py\", line 31, in error_translator\n",
      "    raise errors_impl.NotFoundError(None, None, error_message)\n",
      "tensorflow.python.framework.errors_impl.NotFoundError: Unsuccessful TensorSliceReader constructor: Failed to find any matching files for ./tmp/checkpoint\n",
      "\n",
      "During handling of the above exception, another exception occurred:\n",
      "\n",
      "Traceback (most recent call last):\n",
      "  File \"C:\\Users\\ngden\\AppData\\Roaming\\Python\\Python310\\site-packages\\IPython\\core\\interactiveshell.py\", line 2105, in showtraceback\n",
      "    stb = self.InteractiveTB.structured_traceback(\n",
      "  File \"C:\\Users\\ngden\\AppData\\Roaming\\Python\\Python310\\site-packages\\IPython\\core\\ultratb.py\", line 1428, in structured_traceback\n",
      "    return FormattedTB.structured_traceback(\n",
      "  File \"C:\\Users\\ngden\\AppData\\Roaming\\Python\\Python310\\site-packages\\IPython\\core\\ultratb.py\", line 1319, in structured_traceback\n",
      "    return VerboseTB.structured_traceback(\n",
      "  File \"C:\\Users\\ngden\\AppData\\Roaming\\Python\\Python310\\site-packages\\IPython\\core\\ultratb.py\", line 1172, in structured_traceback\n",
      "    formatted_exception = self.format_exception_as_a_whole(etype, evalue, etb, number_of_lines_of_context,\n",
      "  File \"C:\\Users\\ngden\\AppData\\Roaming\\Python\\Python310\\site-packages\\IPython\\core\\ultratb.py\", line 1087, in format_exception_as_a_whole\n",
      "    frames.append(self.format_record(record))\n",
      "  File \"C:\\Users\\ngden\\AppData\\Roaming\\Python\\Python310\\site-packages\\IPython\\core\\ultratb.py\", line 969, in format_record\n",
      "    frame_info.lines, Colors, self.has_colors, lvals\n",
      "  File \"C:\\Users\\ngden\\AppData\\Roaming\\Python\\Python310\\site-packages\\IPython\\core\\ultratb.py\", line 792, in lines\n",
      "    return self._sd.lines\n",
      "  File \"C:\\Users\\ngden\\AppData\\Roaming\\Python\\Python310\\site-packages\\stack_data\\utils.py\", line 144, in cached_property_wrapper\n",
      "    value = obj.__dict__[self.func.__name__] = self.func(obj)\n",
      "  File \"C:\\Users\\ngden\\AppData\\Roaming\\Python\\Python310\\site-packages\\stack_data\\core.py\", line 734, in lines\n",
      "    pieces = self.included_pieces\n",
      "  File \"C:\\Users\\ngden\\AppData\\Roaming\\Python\\Python310\\site-packages\\stack_data\\utils.py\", line 144, in cached_property_wrapper\n",
      "    value = obj.__dict__[self.func.__name__] = self.func(obj)\n",
      "  File \"C:\\Users\\ngden\\AppData\\Roaming\\Python\\Python310\\site-packages\\stack_data\\core.py\", line 677, in included_pieces\n",
      "    scope_pieces = self.scope_pieces\n",
      "  File \"C:\\Users\\ngden\\AppData\\Roaming\\Python\\Python310\\site-packages\\stack_data\\utils.py\", line 144, in cached_property_wrapper\n",
      "    value = obj.__dict__[self.func.__name__] = self.func(obj)\n",
      "  File \"C:\\Users\\ngden\\AppData\\Roaming\\Python\\Python310\\site-packages\\stack_data\\core.py\", line 614, in scope_pieces\n",
      "    scope_start, scope_end = self.source.line_range(self.scope)\n",
      "  File \"C:\\Users\\ngden\\AppData\\Roaming\\Python\\Python310\\site-packages\\stack_data\\core.py\", line 178, in line_range\n",
      "    return line_range(self.asttext(), node)\n",
      "AttributeError: 'Source' object has no attribute 'asttext'\n"
     ]
    }
   ],
   "source": [
    "# OPTIONAL: Decide if best weights should be loaded from previous model based on val_acc\n",
    "# The model weights (that are considered the best) are loaded into the model.\n",
    "result = model.load_weights(checkpoint_filepath)"
   ]
  },
  {
   "cell_type": "code",
   "execution_count": 13,
   "metadata": {},
   "outputs": [],
   "source": [
    "#change the directory back to initial path (Image Classification folder)\n",
    "os.chdir(\"../..\")\n",
    "# os.listdir()\n",
    "\n",
    "#save the model\n",
    "model.save(\"Models/VGG19/VGG19_covid_classification.h5\")\n",
    "\n",
    "os.chdir(destination)"
   ]
  },
  {
   "cell_type": "markdown",
   "metadata": {},
   "source": [
    "<h3>Evaluate Test data</h3>"
   ]
  },
  {
   "cell_type": "code",
   "execution_count": 14,
   "metadata": {},
   "outputs": [
    {
     "name": "stdout",
     "output_type": "stream",
     "text": [
      "0.0\n",
      "Unexpected exception formatting exception. Falling back to standard exception\n"
     ]
    },
    {
     "name": "stderr",
     "output_type": "stream",
     "text": [
      "Traceback (most recent call last):\n",
      "  File \"C:\\Users\\ngden\\AppData\\Roaming\\Python\\Python310\\site-packages\\IPython\\core\\interactiveshell.py\", line 3508, in run_code\n",
      "    exec(code_obj, self.user_global_ns, self.user_ns)\n",
      "  File \"C:\\Users\\ngden\\AppData\\Local\\Temp\\ipykernel_728\\3409139554.py\", line 3, in <module>\n",
      "    testLoss, testAcc = model.evaluate(test)\n",
      "  File \"c:\\Users\\ngden\\anaconda3\\lib\\site-packages\\keras\\utils\\traceback_utils.py\", line 70, in error_handler\n",
      "    raise e.with_traceback(filtered_tb) from None\n",
      "  File \"c:\\Users\\ngden\\anaconda3\\lib\\site-packages\\tensorflow\\python\\eager\\execute.py\", line 54, in quick_execute\n",
      "    tensors = pywrap_tfe.TFE_Py_Execute(ctx._handle, device_name, op_name,\n",
      "tensorflow.python.framework.errors_impl.ResourceExhaustedError: Graph execution error:\n",
      "\n",
      "Detected at node 'model/vgg19/block1_conv2/Relu' defined at (most recent call last):\n",
      "    File \"c:\\Users\\ngden\\anaconda3\\lib\\runpy.py\", line 196, in _run_module_as_main\n",
      "      return _run_code(code, main_globals, None,\n",
      "    File \"c:\\Users\\ngden\\anaconda3\\lib\\runpy.py\", line 86, in _run_code\n",
      "      exec(code, run_globals)\n",
      "    File \"C:\\Users\\ngden\\AppData\\Roaming\\Python\\Python310\\site-packages\\ipykernel_launcher.py\", line 17, in <module>\n",
      "      app.launch_new_instance()\n",
      "    File \"C:\\Users\\ngden\\AppData\\Roaming\\Python\\Python310\\site-packages\\traitlets\\config\\application.py\", line 1043, in launch_instance\n",
      "      app.start()\n",
      "    File \"C:\\Users\\ngden\\AppData\\Roaming\\Python\\Python310\\site-packages\\ipykernel\\kernelapp.py\", line 728, in start\n",
      "      self.io_loop.start()\n",
      "    File \"C:\\Users\\ngden\\AppData\\Roaming\\Python\\Python310\\site-packages\\tornado\\platform\\asyncio.py\", line 195, in start\n",
      "      self.asyncio_loop.run_forever()\n",
      "    File \"c:\\Users\\ngden\\anaconda3\\lib\\asyncio\\base_events.py\", line 603, in run_forever\n",
      "      self._run_once()\n",
      "    File \"c:\\Users\\ngden\\anaconda3\\lib\\asyncio\\base_events.py\", line 1906, in _run_once\n",
      "      handle._run()\n",
      "    File \"c:\\Users\\ngden\\anaconda3\\lib\\asyncio\\events.py\", line 80, in _run\n",
      "      self._context.run(self._callback, *self._args)\n",
      "    File \"C:\\Users\\ngden\\AppData\\Roaming\\Python\\Python310\\site-packages\\ipykernel\\kernelbase.py\", line 516, in dispatch_queue\n",
      "      await self.process_one()\n",
      "    File \"C:\\Users\\ngden\\AppData\\Roaming\\Python\\Python310\\site-packages\\ipykernel\\kernelbase.py\", line 505, in process_one\n",
      "      await dispatch(*args)\n",
      "    File \"C:\\Users\\ngden\\AppData\\Roaming\\Python\\Python310\\site-packages\\ipykernel\\kernelbase.py\", line 412, in dispatch_shell\n",
      "      await result\n",
      "    File \"C:\\Users\\ngden\\AppData\\Roaming\\Python\\Python310\\site-packages\\ipykernel\\kernelbase.py\", line 740, in execute_request\n",
      "      reply_content = await reply_content\n",
      "    File \"C:\\Users\\ngden\\AppData\\Roaming\\Python\\Python310\\site-packages\\ipykernel\\ipkernel.py\", line 422, in do_execute\n",
      "      res = shell.run_cell(\n",
      "    File \"C:\\Users\\ngden\\AppData\\Roaming\\Python\\Python310\\site-packages\\ipykernel\\zmqshell.py\", line 540, in run_cell\n",
      "      return super().run_cell(*args, **kwargs)\n",
      "    File \"C:\\Users\\ngden\\AppData\\Roaming\\Python\\Python310\\site-packages\\IPython\\core\\interactiveshell.py\", line 3009, in run_cell\n",
      "      result = self._run_cell(\n",
      "    File \"C:\\Users\\ngden\\AppData\\Roaming\\Python\\Python310\\site-packages\\IPython\\core\\interactiveshell.py\", line 3064, in _run_cell\n",
      "      result = runner(coro)\n",
      "    File \"C:\\Users\\ngden\\AppData\\Roaming\\Python\\Python310\\site-packages\\IPython\\core\\async_helpers.py\", line 129, in _pseudo_sync_runner\n",
      "      coro.send(None)\n",
      "    File \"C:\\Users\\ngden\\AppData\\Roaming\\Python\\Python310\\site-packages\\IPython\\core\\interactiveshell.py\", line 3269, in run_cell_async\n",
      "      has_raised = await self.run_ast_nodes(code_ast.body, cell_name,\n",
      "    File \"C:\\Users\\ngden\\AppData\\Roaming\\Python\\Python310\\site-packages\\IPython\\core\\interactiveshell.py\", line 3448, in run_ast_nodes\n",
      "      if await self.run_code(code, result, async_=asy):\n",
      "    File \"C:\\Users\\ngden\\AppData\\Roaming\\Python\\Python310\\site-packages\\IPython\\core\\interactiveshell.py\", line 3508, in run_code\n",
      "      exec(code_obj, self.user_global_ns, self.user_ns)\n",
      "    File \"C:\\Users\\ngden\\AppData\\Local\\Temp\\ipykernel_728\\3409139554.py\", line 3, in <module>\n",
      "      testLoss, testAcc = model.evaluate(test)\n",
      "    File \"c:\\Users\\ngden\\anaconda3\\lib\\site-packages\\keras\\utils\\traceback_utils.py\", line 65, in error_handler\n",
      "      return fn(*args, **kwargs)\n",
      "    File \"c:\\Users\\ngden\\anaconda3\\lib\\site-packages\\keras\\engine\\training.py\", line 1947, in evaluate\n",
      "      tmp_logs = self.test_function(iterator)\n",
      "    File \"c:\\Users\\ngden\\anaconda3\\lib\\site-packages\\keras\\engine\\training.py\", line 1727, in test_function\n",
      "      return step_function(self, iterator)\n",
      "    File \"c:\\Users\\ngden\\anaconda3\\lib\\site-packages\\keras\\engine\\training.py\", line 1713, in step_function\n",
      "      outputs = model.distribute_strategy.run(run_step, args=(data,))\n",
      "    File \"c:\\Users\\ngden\\anaconda3\\lib\\site-packages\\keras\\engine\\training.py\", line 1701, in run_step\n",
      "      outputs = model.test_step(data)\n",
      "    File \"c:\\Users\\ngden\\anaconda3\\lib\\site-packages\\keras\\engine\\training.py\", line 1665, in test_step\n",
      "      y_pred = self(x, training=False)\n",
      "    File \"c:\\Users\\ngden\\anaconda3\\lib\\site-packages\\keras\\utils\\traceback_utils.py\", line 65, in error_handler\n",
      "      return fn(*args, **kwargs)\n",
      "    File \"c:\\Users\\ngden\\anaconda3\\lib\\site-packages\\keras\\engine\\training.py\", line 557, in __call__\n",
      "      return super().__call__(*args, **kwargs)\n",
      "    File \"c:\\Users\\ngden\\anaconda3\\lib\\site-packages\\keras\\utils\\traceback_utils.py\", line 65, in error_handler\n",
      "      return fn(*args, **kwargs)\n",
      "    File \"c:\\Users\\ngden\\anaconda3\\lib\\site-packages\\keras\\engine\\base_layer.py\", line 1097, in __call__\n",
      "      outputs = call_fn(inputs, *args, **kwargs)\n",
      "    File \"c:\\Users\\ngden\\anaconda3\\lib\\site-packages\\keras\\utils\\traceback_utils.py\", line 96, in error_handler\n",
      "      return fn(*args, **kwargs)\n",
      "    File \"c:\\Users\\ngden\\anaconda3\\lib\\site-packages\\keras\\engine\\functional.py\", line 510, in call\n",
      "      return self._run_internal_graph(inputs, training=training, mask=mask)\n",
      "    File \"c:\\Users\\ngden\\anaconda3\\lib\\site-packages\\keras\\engine\\functional.py\", line 667, in _run_internal_graph\n",
      "      outputs = node.layer(*args, **kwargs)\n",
      "    File \"c:\\Users\\ngden\\anaconda3\\lib\\site-packages\\keras\\utils\\traceback_utils.py\", line 65, in error_handler\n",
      "      return fn(*args, **kwargs)\n",
      "    File \"c:\\Users\\ngden\\anaconda3\\lib\\site-packages\\keras\\engine\\training.py\", line 557, in __call__\n",
      "      return super().__call__(*args, **kwargs)\n",
      "    File \"c:\\Users\\ngden\\anaconda3\\lib\\site-packages\\keras\\utils\\traceback_utils.py\", line 65, in error_handler\n",
      "      return fn(*args, **kwargs)\n",
      "    File \"c:\\Users\\ngden\\anaconda3\\lib\\site-packages\\keras\\engine\\base_layer.py\", line 1097, in __call__\n",
      "      outputs = call_fn(inputs, *args, **kwargs)\n",
      "    File \"c:\\Users\\ngden\\anaconda3\\lib\\site-packages\\keras\\utils\\traceback_utils.py\", line 96, in error_handler\n",
      "      return fn(*args, **kwargs)\n",
      "    File \"c:\\Users\\ngden\\anaconda3\\lib\\site-packages\\keras\\engine\\functional.py\", line 510, in call\n",
      "      return self._run_internal_graph(inputs, training=training, mask=mask)\n",
      "    File \"c:\\Users\\ngden\\anaconda3\\lib\\site-packages\\keras\\engine\\functional.py\", line 667, in _run_internal_graph\n",
      "      outputs = node.layer(*args, **kwargs)\n",
      "    File \"c:\\Users\\ngden\\anaconda3\\lib\\site-packages\\keras\\utils\\traceback_utils.py\", line 65, in error_handler\n",
      "      return fn(*args, **kwargs)\n",
      "    File \"c:\\Users\\ngden\\anaconda3\\lib\\site-packages\\keras\\engine\\base_layer.py\", line 1097, in __call__\n",
      "      outputs = call_fn(inputs, *args, **kwargs)\n",
      "    File \"c:\\Users\\ngden\\anaconda3\\lib\\site-packages\\keras\\utils\\traceback_utils.py\", line 96, in error_handler\n",
      "      return fn(*args, **kwargs)\n",
      "    File \"c:\\Users\\ngden\\anaconda3\\lib\\site-packages\\keras\\layers\\convolutional\\base_conv.py\", line 314, in call\n",
      "      return self.activation(outputs)\n",
      "    File \"c:\\Users\\ngden\\anaconda3\\lib\\site-packages\\keras\\activations.py\", line 317, in relu\n",
      "      return backend.relu(\n",
      "    File \"c:\\Users\\ngden\\anaconda3\\lib\\site-packages\\keras\\backend.py\", line 5366, in relu\n",
      "      x = tf.nn.relu(x)\n",
      "Node: 'model/vgg19/block1_conv2/Relu'\n",
      "OOM when allocating tensor with shape[32,64,224,224] and type float on /job:localhost/replica:0/task:0/device:GPU:0 by allocator GPU_0_bfc\n",
      "\t [[{{node model/vgg19/block1_conv2/Relu}}]]\n",
      "Hint: If you want to see a list of allocated tensors when OOM happens, add report_tensor_allocations_upon_oom to RunOptions for current allocation info. This isn't available when running in Eager mode.\n",
      " [Op:__inference_test_function_2096]\n",
      "\n",
      "During handling of the above exception, another exception occurred:\n",
      "\n",
      "Traceback (most recent call last):\n",
      "  File \"C:\\Users\\ngden\\AppData\\Roaming\\Python\\Python310\\site-packages\\IPython\\core\\interactiveshell.py\", line 2105, in showtraceback\n",
      "    stb = self.InteractiveTB.structured_traceback(\n",
      "  File \"C:\\Users\\ngden\\AppData\\Roaming\\Python\\Python310\\site-packages\\IPython\\core\\ultratb.py\", line 1428, in structured_traceback\n",
      "    return FormattedTB.structured_traceback(\n",
      "  File \"C:\\Users\\ngden\\AppData\\Roaming\\Python\\Python310\\site-packages\\IPython\\core\\ultratb.py\", line 1319, in structured_traceback\n",
      "    return VerboseTB.structured_traceback(\n",
      "  File \"C:\\Users\\ngden\\AppData\\Roaming\\Python\\Python310\\site-packages\\IPython\\core\\ultratb.py\", line 1172, in structured_traceback\n",
      "    formatted_exception = self.format_exception_as_a_whole(etype, evalue, etb, number_of_lines_of_context,\n",
      "  File \"C:\\Users\\ngden\\AppData\\Roaming\\Python\\Python310\\site-packages\\IPython\\core\\ultratb.py\", line 1087, in format_exception_as_a_whole\n",
      "    frames.append(self.format_record(record))\n",
      "  File \"C:\\Users\\ngden\\AppData\\Roaming\\Python\\Python310\\site-packages\\IPython\\core\\ultratb.py\", line 969, in format_record\n",
      "    frame_info.lines, Colors, self.has_colors, lvals\n",
      "  File \"C:\\Users\\ngden\\AppData\\Roaming\\Python\\Python310\\site-packages\\IPython\\core\\ultratb.py\", line 792, in lines\n",
      "    return self._sd.lines\n",
      "  File \"C:\\Users\\ngden\\AppData\\Roaming\\Python\\Python310\\site-packages\\stack_data\\utils.py\", line 144, in cached_property_wrapper\n",
      "    value = obj.__dict__[self.func.__name__] = self.func(obj)\n",
      "  File \"C:\\Users\\ngden\\AppData\\Roaming\\Python\\Python310\\site-packages\\stack_data\\core.py\", line 734, in lines\n",
      "    pieces = self.included_pieces\n",
      "  File \"C:\\Users\\ngden\\AppData\\Roaming\\Python\\Python310\\site-packages\\stack_data\\utils.py\", line 144, in cached_property_wrapper\n",
      "    value = obj.__dict__[self.func.__name__] = self.func(obj)\n",
      "  File \"C:\\Users\\ngden\\AppData\\Roaming\\Python\\Python310\\site-packages\\stack_data\\core.py\", line 677, in included_pieces\n",
      "    scope_pieces = self.scope_pieces\n",
      "  File \"C:\\Users\\ngden\\AppData\\Roaming\\Python\\Python310\\site-packages\\stack_data\\utils.py\", line 144, in cached_property_wrapper\n",
      "    value = obj.__dict__[self.func.__name__] = self.func(obj)\n",
      "  File \"C:\\Users\\ngden\\AppData\\Roaming\\Python\\Python310\\site-packages\\stack_data\\core.py\", line 614, in scope_pieces\n",
      "    scope_start, scope_end = self.source.line_range(self.scope)\n",
      "  File \"C:\\Users\\ngden\\AppData\\Roaming\\Python\\Python310\\site-packages\\stack_data\\core.py\", line 178, in line_range\n",
      "    return line_range(self.asttext(), node)\n",
      "AttributeError: 'Source' object has no attribute 'asttext'\n"
     ]
    }
   ],
   "source": [
    "print(sum(cb.logs) / 150)\n",
    "\n",
    "testLoss, testAcc = model.evaluate(test)\n",
    "print('''\n",
    "Test Loss: {}\n",
    "Test Accuracy: {}\n",
    "'''.format(testLoss, testAcc))"
   ]
  },
  {
   "cell_type": "markdown",
   "metadata": {},
   "source": [
    "<h4>*Optional - Fine tune model with two-step training*</h4>"
   ]
  },
  {
   "cell_type": "code",
   "execution_count": 15,
   "metadata": {},
   "outputs": [
    {
     "name": "stdout",
     "output_type": "stream",
     "text": [
      "Epoch 1/100\n",
      "Unexpected exception formatting exception. Falling back to standard exception\n"
     ]
    },
    {
     "name": "stderr",
     "output_type": "stream",
     "text": [
      "Traceback (most recent call last):\n",
      "  File \"C:\\Users\\ngden\\AppData\\Roaming\\Python\\Python310\\site-packages\\IPython\\core\\interactiveshell.py\", line 3508, in run_code\n",
      "    exec(code_obj, self.user_global_ns, self.user_ns)\n",
      "  File \"C:\\Users\\ngden\\AppData\\Local\\Temp\\ipykernel_728\\3628897334.py\", line 11, in <module>\n",
      "    result = model.fit(x=train, validation_data=validation, epochs=100, verbose=2, callbacks=[cb, es])\n",
      "  File \"c:\\Users\\ngden\\anaconda3\\lib\\site-packages\\keras\\utils\\traceback_utils.py\", line 70, in error_handler\n",
      "    raise e.with_traceback(filtered_tb) from None\n",
      "  File \"c:\\Users\\ngden\\anaconda3\\lib\\site-packages\\tensorflow\\python\\eager\\execute.py\", line 54, in quick_execute\n",
      "    tensors = pywrap_tfe.TFE_Py_Execute(ctx._handle, device_name, op_name,\n",
      "tensorflow.python.framework.errors_impl.ResourceExhaustedError: Graph execution error:\n",
      "\n",
      "Detected at node 'model/vgg19/block1_conv2/Relu' defined at (most recent call last):\n",
      "    File \"c:\\Users\\ngden\\anaconda3\\lib\\runpy.py\", line 196, in _run_module_as_main\n",
      "      return _run_code(code, main_globals, None,\n",
      "    File \"c:\\Users\\ngden\\anaconda3\\lib\\runpy.py\", line 86, in _run_code\n",
      "      exec(code, run_globals)\n",
      "    File \"C:\\Users\\ngden\\AppData\\Roaming\\Python\\Python310\\site-packages\\ipykernel_launcher.py\", line 17, in <module>\n",
      "      app.launch_new_instance()\n",
      "    File \"C:\\Users\\ngden\\AppData\\Roaming\\Python\\Python310\\site-packages\\traitlets\\config\\application.py\", line 1043, in launch_instance\n",
      "      app.start()\n",
      "    File \"C:\\Users\\ngden\\AppData\\Roaming\\Python\\Python310\\site-packages\\ipykernel\\kernelapp.py\", line 728, in start\n",
      "      self.io_loop.start()\n",
      "    File \"C:\\Users\\ngden\\AppData\\Roaming\\Python\\Python310\\site-packages\\tornado\\platform\\asyncio.py\", line 195, in start\n",
      "      self.asyncio_loop.run_forever()\n",
      "    File \"c:\\Users\\ngden\\anaconda3\\lib\\asyncio\\base_events.py\", line 603, in run_forever\n",
      "      self._run_once()\n",
      "    File \"c:\\Users\\ngden\\anaconda3\\lib\\asyncio\\base_events.py\", line 1906, in _run_once\n",
      "      handle._run()\n",
      "    File \"c:\\Users\\ngden\\anaconda3\\lib\\asyncio\\events.py\", line 80, in _run\n",
      "      self._context.run(self._callback, *self._args)\n",
      "    File \"C:\\Users\\ngden\\AppData\\Roaming\\Python\\Python310\\site-packages\\ipykernel\\kernelbase.py\", line 516, in dispatch_queue\n",
      "      await self.process_one()\n",
      "    File \"C:\\Users\\ngden\\AppData\\Roaming\\Python\\Python310\\site-packages\\ipykernel\\kernelbase.py\", line 505, in process_one\n",
      "      await dispatch(*args)\n",
      "    File \"C:\\Users\\ngden\\AppData\\Roaming\\Python\\Python310\\site-packages\\ipykernel\\kernelbase.py\", line 412, in dispatch_shell\n",
      "      await result\n",
      "    File \"C:\\Users\\ngden\\AppData\\Roaming\\Python\\Python310\\site-packages\\ipykernel\\kernelbase.py\", line 740, in execute_request\n",
      "      reply_content = await reply_content\n",
      "    File \"C:\\Users\\ngden\\AppData\\Roaming\\Python\\Python310\\site-packages\\ipykernel\\ipkernel.py\", line 422, in do_execute\n",
      "      res = shell.run_cell(\n",
      "    File \"C:\\Users\\ngden\\AppData\\Roaming\\Python\\Python310\\site-packages\\ipykernel\\zmqshell.py\", line 540, in run_cell\n",
      "      return super().run_cell(*args, **kwargs)\n",
      "    File \"C:\\Users\\ngden\\AppData\\Roaming\\Python\\Python310\\site-packages\\IPython\\core\\interactiveshell.py\", line 3009, in run_cell\n",
      "      result = self._run_cell(\n",
      "    File \"C:\\Users\\ngden\\AppData\\Roaming\\Python\\Python310\\site-packages\\IPython\\core\\interactiveshell.py\", line 3064, in _run_cell\n",
      "      result = runner(coro)\n",
      "    File \"C:\\Users\\ngden\\AppData\\Roaming\\Python\\Python310\\site-packages\\IPython\\core\\async_helpers.py\", line 129, in _pseudo_sync_runner\n",
      "      coro.send(None)\n",
      "    File \"C:\\Users\\ngden\\AppData\\Roaming\\Python\\Python310\\site-packages\\IPython\\core\\interactiveshell.py\", line 3269, in run_cell_async\n",
      "      has_raised = await self.run_ast_nodes(code_ast.body, cell_name,\n",
      "    File \"C:\\Users\\ngden\\AppData\\Roaming\\Python\\Python310\\site-packages\\IPython\\core\\interactiveshell.py\", line 3448, in run_ast_nodes\n",
      "      if await self.run_code(code, result, async_=asy):\n",
      "    File \"C:\\Users\\ngden\\AppData\\Roaming\\Python\\Python310\\site-packages\\IPython\\core\\interactiveshell.py\", line 3508, in run_code\n",
      "      exec(code_obj, self.user_global_ns, self.user_ns)\n",
      "    File \"C:\\Users\\ngden\\AppData\\Local\\Temp\\ipykernel_728\\3628897334.py\", line 11, in <module>\n",
      "      result = model.fit(x=train, validation_data=validation, epochs=100, verbose=2, callbacks=[cb, es])\n",
      "    File \"c:\\Users\\ngden\\anaconda3\\lib\\site-packages\\keras\\utils\\traceback_utils.py\", line 65, in error_handler\n",
      "      return fn(*args, **kwargs)\n",
      "    File \"c:\\Users\\ngden\\anaconda3\\lib\\site-packages\\keras\\engine\\training.py\", line 1564, in fit\n",
      "      tmp_logs = self.train_function(iterator)\n",
      "    File \"c:\\Users\\ngden\\anaconda3\\lib\\site-packages\\keras\\engine\\training.py\", line 1160, in train_function\n",
      "      return step_function(self, iterator)\n",
      "    File \"c:\\Users\\ngden\\anaconda3\\lib\\site-packages\\keras\\engine\\training.py\", line 1146, in step_function\n",
      "      outputs = model.distribute_strategy.run(run_step, args=(data,))\n",
      "    File \"c:\\Users\\ngden\\anaconda3\\lib\\site-packages\\keras\\engine\\training.py\", line 1135, in run_step\n",
      "      outputs = model.train_step(data)\n",
      "    File \"c:\\Users\\ngden\\anaconda3\\lib\\site-packages\\keras\\engine\\training.py\", line 993, in train_step\n",
      "      y_pred = self(x, training=True)\n",
      "    File \"c:\\Users\\ngden\\anaconda3\\lib\\site-packages\\keras\\utils\\traceback_utils.py\", line 65, in error_handler\n",
      "      return fn(*args, **kwargs)\n",
      "    File \"c:\\Users\\ngden\\anaconda3\\lib\\site-packages\\keras\\engine\\training.py\", line 557, in __call__\n",
      "      return super().__call__(*args, **kwargs)\n",
      "    File \"c:\\Users\\ngden\\anaconda3\\lib\\site-packages\\keras\\utils\\traceback_utils.py\", line 65, in error_handler\n",
      "      return fn(*args, **kwargs)\n",
      "    File \"c:\\Users\\ngden\\anaconda3\\lib\\site-packages\\keras\\engine\\base_layer.py\", line 1097, in __call__\n",
      "      outputs = call_fn(inputs, *args, **kwargs)\n",
      "    File \"c:\\Users\\ngden\\anaconda3\\lib\\site-packages\\keras\\utils\\traceback_utils.py\", line 96, in error_handler\n",
      "      return fn(*args, **kwargs)\n",
      "    File \"c:\\Users\\ngden\\anaconda3\\lib\\site-packages\\keras\\engine\\functional.py\", line 510, in call\n",
      "      return self._run_internal_graph(inputs, training=training, mask=mask)\n",
      "    File \"c:\\Users\\ngden\\anaconda3\\lib\\site-packages\\keras\\engine\\functional.py\", line 667, in _run_internal_graph\n",
      "      outputs = node.layer(*args, **kwargs)\n",
      "    File \"c:\\Users\\ngden\\anaconda3\\lib\\site-packages\\keras\\utils\\traceback_utils.py\", line 65, in error_handler\n",
      "      return fn(*args, **kwargs)\n",
      "    File \"c:\\Users\\ngden\\anaconda3\\lib\\site-packages\\keras\\engine\\training.py\", line 557, in __call__\n",
      "      return super().__call__(*args, **kwargs)\n",
      "    File \"c:\\Users\\ngden\\anaconda3\\lib\\site-packages\\keras\\utils\\traceback_utils.py\", line 65, in error_handler\n",
      "      return fn(*args, **kwargs)\n",
      "    File \"c:\\Users\\ngden\\anaconda3\\lib\\site-packages\\keras\\engine\\base_layer.py\", line 1097, in __call__\n",
      "      outputs = call_fn(inputs, *args, **kwargs)\n",
      "    File \"c:\\Users\\ngden\\anaconda3\\lib\\site-packages\\keras\\utils\\traceback_utils.py\", line 96, in error_handler\n",
      "      return fn(*args, **kwargs)\n",
      "    File \"c:\\Users\\ngden\\anaconda3\\lib\\site-packages\\keras\\engine\\functional.py\", line 510, in call\n",
      "      return self._run_internal_graph(inputs, training=training, mask=mask)\n",
      "    File \"c:\\Users\\ngden\\anaconda3\\lib\\site-packages\\keras\\engine\\functional.py\", line 667, in _run_internal_graph\n",
      "      outputs = node.layer(*args, **kwargs)\n",
      "    File \"c:\\Users\\ngden\\anaconda3\\lib\\site-packages\\keras\\utils\\traceback_utils.py\", line 65, in error_handler\n",
      "      return fn(*args, **kwargs)\n",
      "    File \"c:\\Users\\ngden\\anaconda3\\lib\\site-packages\\keras\\engine\\base_layer.py\", line 1097, in __call__\n",
      "      outputs = call_fn(inputs, *args, **kwargs)\n",
      "    File \"c:\\Users\\ngden\\anaconda3\\lib\\site-packages\\keras\\utils\\traceback_utils.py\", line 96, in error_handler\n",
      "      return fn(*args, **kwargs)\n",
      "    File \"c:\\Users\\ngden\\anaconda3\\lib\\site-packages\\keras\\layers\\convolutional\\base_conv.py\", line 314, in call\n",
      "      return self.activation(outputs)\n",
      "    File \"c:\\Users\\ngden\\anaconda3\\lib\\site-packages\\keras\\activations.py\", line 317, in relu\n",
      "      return backend.relu(\n",
      "    File \"c:\\Users\\ngden\\anaconda3\\lib\\site-packages\\keras\\backend.py\", line 5366, in relu\n",
      "      x = tf.nn.relu(x)\n",
      "Node: 'model/vgg19/block1_conv2/Relu'\n",
      "OOM when allocating tensor with shape[32,64,224,224] and type float on /job:localhost/replica:0/task:0/device:GPU:0 by allocator GPU_0_bfc\n",
      "\t [[{{node model/vgg19/block1_conv2/Relu}}]]\n",
      "Hint: If you want to see a list of allocated tensors when OOM happens, add report_tensor_allocations_upon_oom to RunOptions for current allocation info. This isn't available when running in Eager mode.\n",
      " [Op:__inference_train_function_3195]\n",
      "\n",
      "During handling of the above exception, another exception occurred:\n",
      "\n",
      "Traceback (most recent call last):\n",
      "  File \"C:\\Users\\ngden\\AppData\\Roaming\\Python\\Python310\\site-packages\\IPython\\core\\interactiveshell.py\", line 2105, in showtraceback\n",
      "    stb = self.InteractiveTB.structured_traceback(\n",
      "  File \"C:\\Users\\ngden\\AppData\\Roaming\\Python\\Python310\\site-packages\\IPython\\core\\ultratb.py\", line 1428, in structured_traceback\n",
      "    return FormattedTB.structured_traceback(\n",
      "  File \"C:\\Users\\ngden\\AppData\\Roaming\\Python\\Python310\\site-packages\\IPython\\core\\ultratb.py\", line 1319, in structured_traceback\n",
      "    return VerboseTB.structured_traceback(\n",
      "  File \"C:\\Users\\ngden\\AppData\\Roaming\\Python\\Python310\\site-packages\\IPython\\core\\ultratb.py\", line 1172, in structured_traceback\n",
      "    formatted_exception = self.format_exception_as_a_whole(etype, evalue, etb, number_of_lines_of_context,\n",
      "  File \"C:\\Users\\ngden\\AppData\\Roaming\\Python\\Python310\\site-packages\\IPython\\core\\ultratb.py\", line 1087, in format_exception_as_a_whole\n",
      "    frames.append(self.format_record(record))\n",
      "  File \"C:\\Users\\ngden\\AppData\\Roaming\\Python\\Python310\\site-packages\\IPython\\core\\ultratb.py\", line 969, in format_record\n",
      "    frame_info.lines, Colors, self.has_colors, lvals\n",
      "  File \"C:\\Users\\ngden\\AppData\\Roaming\\Python\\Python310\\site-packages\\IPython\\core\\ultratb.py\", line 792, in lines\n",
      "    return self._sd.lines\n",
      "  File \"C:\\Users\\ngden\\AppData\\Roaming\\Python\\Python310\\site-packages\\stack_data\\utils.py\", line 144, in cached_property_wrapper\n",
      "    value = obj.__dict__[self.func.__name__] = self.func(obj)\n",
      "  File \"C:\\Users\\ngden\\AppData\\Roaming\\Python\\Python310\\site-packages\\stack_data\\core.py\", line 734, in lines\n",
      "    pieces = self.included_pieces\n",
      "  File \"C:\\Users\\ngden\\AppData\\Roaming\\Python\\Python310\\site-packages\\stack_data\\utils.py\", line 144, in cached_property_wrapper\n",
      "    value = obj.__dict__[self.func.__name__] = self.func(obj)\n",
      "  File \"C:\\Users\\ngden\\AppData\\Roaming\\Python\\Python310\\site-packages\\stack_data\\core.py\", line 677, in included_pieces\n",
      "    scope_pieces = self.scope_pieces\n",
      "  File \"C:\\Users\\ngden\\AppData\\Roaming\\Python\\Python310\\site-packages\\stack_data\\utils.py\", line 144, in cached_property_wrapper\n",
      "    value = obj.__dict__[self.func.__name__] = self.func(obj)\n",
      "  File \"C:\\Users\\ngden\\AppData\\Roaming\\Python\\Python310\\site-packages\\stack_data\\core.py\", line 614, in scope_pieces\n",
      "    scope_start, scope_end = self.source.line_range(self.scope)\n",
      "  File \"C:\\Users\\ngden\\AppData\\Roaming\\Python\\Python310\\site-packages\\stack_data\\core.py\", line 178, in line_range\n",
      "    return line_range(self.asttext(), node)\n",
      "AttributeError: 'Source' object has no attribute 'asttext'\n"
     ]
    }
   ],
   "source": [
    "es = EarlyStopping(monitor='val_loss', mode='min', verbose=1, patience=10)\n",
    "\n",
    "mobile.trainable = True\n",
    "\n",
    "for layer in mobile.layers[:-2]:\n",
    "    layer.trainable = False\n",
    "    \n",
    "#re-train the model at a very low learning rate\n",
    "model.compile(optimizer=Adam(learning_rate=0.00006), loss='binary_crossentropy', metrics=['binary_accuracy'])\n",
    "\n",
    "result = model.fit(x=train, validation_data=validation, epochs=100, verbose=2, callbacks=[cb, es])\n"
   ]
  },
  {
   "cell_type": "markdown",
   "metadata": {},
   "source": [
    "<h3>Accuracy and Loss graph</h3>"
   ]
  },
  {
   "cell_type": "code",
   "execution_count": 16,
   "metadata": {},
   "outputs": [
    {
     "name": "stdout",
     "output_type": "stream",
     "text": [
      "Unexpected exception formatting exception. Falling back to standard exception\n"
     ]
    },
    {
     "name": "stderr",
     "output_type": "stream",
     "text": [
      "Traceback (most recent call last):\n",
      "  File \"C:\\Users\\ngden\\AppData\\Roaming\\Python\\Python310\\site-packages\\IPython\\core\\interactiveshell.py\", line 3508, in run_code\n",
      "    exec(code_obj, self.user_global_ns, self.user_ns)\n",
      "  File \"C:\\Users\\ngden\\AppData\\Local\\Temp\\ipykernel_728\\4012029090.py\", line 2, in <module>\n",
      "    plt.plot(result.history['binary_accuracy'])\n",
      "NameError: name 'result' is not defined\n",
      "\n",
      "During handling of the above exception, another exception occurred:\n",
      "\n",
      "Traceback (most recent call last):\n",
      "  File \"C:\\Users\\ngden\\AppData\\Roaming\\Python\\Python310\\site-packages\\IPython\\core\\interactiveshell.py\", line 2105, in showtraceback\n",
      "    stb = self.InteractiveTB.structured_traceback(\n",
      "  File \"C:\\Users\\ngden\\AppData\\Roaming\\Python\\Python310\\site-packages\\IPython\\core\\ultratb.py\", line 1428, in structured_traceback\n",
      "    return FormattedTB.structured_traceback(\n",
      "  File \"C:\\Users\\ngden\\AppData\\Roaming\\Python\\Python310\\site-packages\\IPython\\core\\ultratb.py\", line 1319, in structured_traceback\n",
      "    return VerboseTB.structured_traceback(\n",
      "  File \"C:\\Users\\ngden\\AppData\\Roaming\\Python\\Python310\\site-packages\\IPython\\core\\ultratb.py\", line 1172, in structured_traceback\n",
      "    formatted_exception = self.format_exception_as_a_whole(etype, evalue, etb, number_of_lines_of_context,\n",
      "  File \"C:\\Users\\ngden\\AppData\\Roaming\\Python\\Python310\\site-packages\\IPython\\core\\ultratb.py\", line 1087, in format_exception_as_a_whole\n",
      "    frames.append(self.format_record(record))\n",
      "  File \"C:\\Users\\ngden\\AppData\\Roaming\\Python\\Python310\\site-packages\\IPython\\core\\ultratb.py\", line 969, in format_record\n",
      "    frame_info.lines, Colors, self.has_colors, lvals\n",
      "  File \"C:\\Users\\ngden\\AppData\\Roaming\\Python\\Python310\\site-packages\\IPython\\core\\ultratb.py\", line 792, in lines\n",
      "    return self._sd.lines\n",
      "  File \"C:\\Users\\ngden\\AppData\\Roaming\\Python\\Python310\\site-packages\\stack_data\\utils.py\", line 144, in cached_property_wrapper\n",
      "    value = obj.__dict__[self.func.__name__] = self.func(obj)\n",
      "  File \"C:\\Users\\ngden\\AppData\\Roaming\\Python\\Python310\\site-packages\\stack_data\\core.py\", line 734, in lines\n",
      "    pieces = self.included_pieces\n",
      "  File \"C:\\Users\\ngden\\AppData\\Roaming\\Python\\Python310\\site-packages\\stack_data\\utils.py\", line 144, in cached_property_wrapper\n",
      "    value = obj.__dict__[self.func.__name__] = self.func(obj)\n",
      "  File \"C:\\Users\\ngden\\AppData\\Roaming\\Python\\Python310\\site-packages\\stack_data\\core.py\", line 677, in included_pieces\n",
      "    scope_pieces = self.scope_pieces\n",
      "  File \"C:\\Users\\ngden\\AppData\\Roaming\\Python\\Python310\\site-packages\\stack_data\\utils.py\", line 144, in cached_property_wrapper\n",
      "    value = obj.__dict__[self.func.__name__] = self.func(obj)\n",
      "  File \"C:\\Users\\ngden\\AppData\\Roaming\\Python\\Python310\\site-packages\\stack_data\\core.py\", line 614, in scope_pieces\n",
      "    scope_start, scope_end = self.source.line_range(self.scope)\n",
      "  File \"C:\\Users\\ngden\\AppData\\Roaming\\Python\\Python310\\site-packages\\stack_data\\core.py\", line 178, in line_range\n",
      "    return line_range(self.asttext(), node)\n",
      "AttributeError: 'Source' object has no attribute 'asttext'\n"
     ]
    }
   ],
   "source": [
    "#accuracy\n",
    "plt.plot(result.history['binary_accuracy'])\n",
    "plt.plot(result.history['val_binary_accuracy'])\n",
    "plt.title('model accuracy')\n",
    "plt.ylabel('accuracy')\n",
    "plt.xlabel('epoch')\n",
    "plt.legend(['Train', 'Validation'], loc='lower right')\n",
    "plt.show()\n",
    "\n",
    "#loss\n",
    "plt.plot(result.history['loss'])\n",
    "plt.plot(result.history['val_loss'])\n",
    "plt.title('model loss')\n",
    "plt.ylabel('loss')\n",
    "plt.xlabel('epoch')\n",
    "plt.legend(['Train', 'Validation'], loc='upper right')\n",
    "plt.show()"
   ]
  },
  {
   "cell_type": "markdown",
   "metadata": {},
   "source": [
    "<h3>Classification report</h3>"
   ]
  },
  {
   "cell_type": "code",
   "execution_count": 17,
   "metadata": {
    "scrolled": true
   },
   "outputs": [
    {
     "name": "stdout",
     "output_type": "stream",
     "text": [
      "Unexpected exception formatting exception. Falling back to standard exception\n"
     ]
    },
    {
     "name": "stderr",
     "output_type": "stream",
     "text": [
      "Traceback (most recent call last):\n",
      "  File \"C:\\Users\\ngden\\AppData\\Roaming\\Python\\Python310\\site-packages\\IPython\\core\\interactiveshell.py\", line 3508, in run_code\n",
      "    exec(code_obj, self.user_global_ns, self.user_ns)\n",
      "  File \"C:\\Users\\ngden\\AppData\\Local\\Temp\\ipykernel_728\\4196624631.py\", line 1, in <module>\n",
      "    predictions = model.predict(test, verbose=0)\n",
      "  File \"c:\\Users\\ngden\\anaconda3\\lib\\site-packages\\keras\\utils\\traceback_utils.py\", line 70, in error_handler\n",
      "    raise e.with_traceback(filtered_tb) from None\n",
      "  File \"c:\\Users\\ngden\\anaconda3\\lib\\site-packages\\tensorflow\\python\\eager\\execute.py\", line 54, in quick_execute\n",
      "    tensors = pywrap_tfe.TFE_Py_Execute(ctx._handle, device_name, op_name,\n",
      "tensorflow.python.framework.errors_impl.ResourceExhaustedError: Graph execution error:\n",
      "\n",
      "Detected at node 'model/vgg19/block1_conv2/Relu' defined at (most recent call last):\n",
      "    File \"c:\\Users\\ngden\\anaconda3\\lib\\runpy.py\", line 196, in _run_module_as_main\n",
      "      return _run_code(code, main_globals, None,\n",
      "    File \"c:\\Users\\ngden\\anaconda3\\lib\\runpy.py\", line 86, in _run_code\n",
      "      exec(code, run_globals)\n",
      "    File \"C:\\Users\\ngden\\AppData\\Roaming\\Python\\Python310\\site-packages\\ipykernel_launcher.py\", line 17, in <module>\n",
      "      app.launch_new_instance()\n",
      "    File \"C:\\Users\\ngden\\AppData\\Roaming\\Python\\Python310\\site-packages\\traitlets\\config\\application.py\", line 1043, in launch_instance\n",
      "      app.start()\n",
      "    File \"C:\\Users\\ngden\\AppData\\Roaming\\Python\\Python310\\site-packages\\ipykernel\\kernelapp.py\", line 728, in start\n",
      "      self.io_loop.start()\n",
      "    File \"C:\\Users\\ngden\\AppData\\Roaming\\Python\\Python310\\site-packages\\tornado\\platform\\asyncio.py\", line 195, in start\n",
      "      self.asyncio_loop.run_forever()\n",
      "    File \"c:\\Users\\ngden\\anaconda3\\lib\\asyncio\\base_events.py\", line 603, in run_forever\n",
      "      self._run_once()\n",
      "    File \"c:\\Users\\ngden\\anaconda3\\lib\\asyncio\\base_events.py\", line 1906, in _run_once\n",
      "      handle._run()\n",
      "    File \"c:\\Users\\ngden\\anaconda3\\lib\\asyncio\\events.py\", line 80, in _run\n",
      "      self._context.run(self._callback, *self._args)\n",
      "    File \"C:\\Users\\ngden\\AppData\\Roaming\\Python\\Python310\\site-packages\\ipykernel\\kernelbase.py\", line 516, in dispatch_queue\n",
      "      await self.process_one()\n",
      "    File \"C:\\Users\\ngden\\AppData\\Roaming\\Python\\Python310\\site-packages\\ipykernel\\kernelbase.py\", line 505, in process_one\n",
      "      await dispatch(*args)\n",
      "    File \"C:\\Users\\ngden\\AppData\\Roaming\\Python\\Python310\\site-packages\\ipykernel\\kernelbase.py\", line 412, in dispatch_shell\n",
      "      await result\n",
      "    File \"C:\\Users\\ngden\\AppData\\Roaming\\Python\\Python310\\site-packages\\ipykernel\\kernelbase.py\", line 740, in execute_request\n",
      "      reply_content = await reply_content\n",
      "    File \"C:\\Users\\ngden\\AppData\\Roaming\\Python\\Python310\\site-packages\\ipykernel\\ipkernel.py\", line 422, in do_execute\n",
      "      res = shell.run_cell(\n",
      "    File \"C:\\Users\\ngden\\AppData\\Roaming\\Python\\Python310\\site-packages\\ipykernel\\zmqshell.py\", line 540, in run_cell\n",
      "      return super().run_cell(*args, **kwargs)\n",
      "    File \"C:\\Users\\ngden\\AppData\\Roaming\\Python\\Python310\\site-packages\\IPython\\core\\interactiveshell.py\", line 3009, in run_cell\n",
      "      result = self._run_cell(\n",
      "    File \"C:\\Users\\ngden\\AppData\\Roaming\\Python\\Python310\\site-packages\\IPython\\core\\interactiveshell.py\", line 3064, in _run_cell\n",
      "      result = runner(coro)\n",
      "    File \"C:\\Users\\ngden\\AppData\\Roaming\\Python\\Python310\\site-packages\\IPython\\core\\async_helpers.py\", line 129, in _pseudo_sync_runner\n",
      "      coro.send(None)\n",
      "    File \"C:\\Users\\ngden\\AppData\\Roaming\\Python\\Python310\\site-packages\\IPython\\core\\interactiveshell.py\", line 3269, in run_cell_async\n",
      "      has_raised = await self.run_ast_nodes(code_ast.body, cell_name,\n",
      "    File \"C:\\Users\\ngden\\AppData\\Roaming\\Python\\Python310\\site-packages\\IPython\\core\\interactiveshell.py\", line 3448, in run_ast_nodes\n",
      "      if await self.run_code(code, result, async_=asy):\n",
      "    File \"C:\\Users\\ngden\\AppData\\Roaming\\Python\\Python310\\site-packages\\IPython\\core\\interactiveshell.py\", line 3508, in run_code\n",
      "      exec(code_obj, self.user_global_ns, self.user_ns)\n",
      "    File \"C:\\Users\\ngden\\AppData\\Local\\Temp\\ipykernel_728\\4196624631.py\", line 1, in <module>\n",
      "      predictions = model.predict(test, verbose=0)\n",
      "    File \"c:\\Users\\ngden\\anaconda3\\lib\\site-packages\\keras\\utils\\traceback_utils.py\", line 65, in error_handler\n",
      "      return fn(*args, **kwargs)\n",
      "    File \"c:\\Users\\ngden\\anaconda3\\lib\\site-packages\\keras\\engine\\training.py\", line 2253, in predict\n",
      "      tmp_batch_outputs = self.predict_function(iterator)\n",
      "    File \"c:\\Users\\ngden\\anaconda3\\lib\\site-packages\\keras\\engine\\training.py\", line 2041, in predict_function\n",
      "      return step_function(self, iterator)\n",
      "    File \"c:\\Users\\ngden\\anaconda3\\lib\\site-packages\\keras\\engine\\training.py\", line 2027, in step_function\n",
      "      outputs = model.distribute_strategy.run(run_step, args=(data,))\n",
      "    File \"c:\\Users\\ngden\\anaconda3\\lib\\site-packages\\keras\\engine\\training.py\", line 2015, in run_step\n",
      "      outputs = model.predict_step(data)\n",
      "    File \"c:\\Users\\ngden\\anaconda3\\lib\\site-packages\\keras\\engine\\training.py\", line 1983, in predict_step\n",
      "      return self(x, training=False)\n",
      "    File \"c:\\Users\\ngden\\anaconda3\\lib\\site-packages\\keras\\utils\\traceback_utils.py\", line 65, in error_handler\n",
      "      return fn(*args, **kwargs)\n",
      "    File \"c:\\Users\\ngden\\anaconda3\\lib\\site-packages\\keras\\engine\\training.py\", line 557, in __call__\n",
      "      return super().__call__(*args, **kwargs)\n",
      "    File \"c:\\Users\\ngden\\anaconda3\\lib\\site-packages\\keras\\utils\\traceback_utils.py\", line 65, in error_handler\n",
      "      return fn(*args, **kwargs)\n",
      "    File \"c:\\Users\\ngden\\anaconda3\\lib\\site-packages\\keras\\engine\\base_layer.py\", line 1097, in __call__\n",
      "      outputs = call_fn(inputs, *args, **kwargs)\n",
      "    File \"c:\\Users\\ngden\\anaconda3\\lib\\site-packages\\keras\\utils\\traceback_utils.py\", line 96, in error_handler\n",
      "      return fn(*args, **kwargs)\n",
      "    File \"c:\\Users\\ngden\\anaconda3\\lib\\site-packages\\keras\\engine\\functional.py\", line 510, in call\n",
      "      return self._run_internal_graph(inputs, training=training, mask=mask)\n",
      "    File \"c:\\Users\\ngden\\anaconda3\\lib\\site-packages\\keras\\engine\\functional.py\", line 667, in _run_internal_graph\n",
      "      outputs = node.layer(*args, **kwargs)\n",
      "    File \"c:\\Users\\ngden\\anaconda3\\lib\\site-packages\\keras\\utils\\traceback_utils.py\", line 65, in error_handler\n",
      "      return fn(*args, **kwargs)\n",
      "    File \"c:\\Users\\ngden\\anaconda3\\lib\\site-packages\\keras\\engine\\training.py\", line 557, in __call__\n",
      "      return super().__call__(*args, **kwargs)\n",
      "    File \"c:\\Users\\ngden\\anaconda3\\lib\\site-packages\\keras\\utils\\traceback_utils.py\", line 65, in error_handler\n",
      "      return fn(*args, **kwargs)\n",
      "    File \"c:\\Users\\ngden\\anaconda3\\lib\\site-packages\\keras\\engine\\base_layer.py\", line 1097, in __call__\n",
      "      outputs = call_fn(inputs, *args, **kwargs)\n",
      "    File \"c:\\Users\\ngden\\anaconda3\\lib\\site-packages\\keras\\utils\\traceback_utils.py\", line 96, in error_handler\n",
      "      return fn(*args, **kwargs)\n",
      "    File \"c:\\Users\\ngden\\anaconda3\\lib\\site-packages\\keras\\engine\\functional.py\", line 510, in call\n",
      "      return self._run_internal_graph(inputs, training=training, mask=mask)\n",
      "    File \"c:\\Users\\ngden\\anaconda3\\lib\\site-packages\\keras\\engine\\functional.py\", line 667, in _run_internal_graph\n",
      "      outputs = node.layer(*args, **kwargs)\n",
      "    File \"c:\\Users\\ngden\\anaconda3\\lib\\site-packages\\keras\\utils\\traceback_utils.py\", line 65, in error_handler\n",
      "      return fn(*args, **kwargs)\n",
      "    File \"c:\\Users\\ngden\\anaconda3\\lib\\site-packages\\keras\\engine\\base_layer.py\", line 1097, in __call__\n",
      "      outputs = call_fn(inputs, *args, **kwargs)\n",
      "    File \"c:\\Users\\ngden\\anaconda3\\lib\\site-packages\\keras\\utils\\traceback_utils.py\", line 96, in error_handler\n",
      "      return fn(*args, **kwargs)\n",
      "    File \"c:\\Users\\ngden\\anaconda3\\lib\\site-packages\\keras\\layers\\convolutional\\base_conv.py\", line 314, in call\n",
      "      return self.activation(outputs)\n",
      "    File \"c:\\Users\\ngden\\anaconda3\\lib\\site-packages\\keras\\activations.py\", line 317, in relu\n",
      "      return backend.relu(\n",
      "    File \"c:\\Users\\ngden\\anaconda3\\lib\\site-packages\\keras\\backend.py\", line 5366, in relu\n",
      "      x = tf.nn.relu(x)\n",
      "Node: 'model/vgg19/block1_conv2/Relu'\n",
      "OOM when allocating tensor with shape[32,64,224,224] and type float on /job:localhost/replica:0/task:0/device:GPU:0 by allocator GPU_0_bfc\n",
      "\t [[{{node model/vgg19/block1_conv2/Relu}}]]\n",
      "Hint: If you want to see a list of allocated tensors when OOM happens, add report_tensor_allocations_upon_oom to RunOptions for current allocation info. This isn't available when running in Eager mode.\n",
      " [Op:__inference_predict_function_3375]\n",
      "\n",
      "During handling of the above exception, another exception occurred:\n",
      "\n",
      "Traceback (most recent call last):\n",
      "  File \"C:\\Users\\ngden\\AppData\\Roaming\\Python\\Python310\\site-packages\\IPython\\core\\interactiveshell.py\", line 2105, in showtraceback\n",
      "    stb = self.InteractiveTB.structured_traceback(\n",
      "  File \"C:\\Users\\ngden\\AppData\\Roaming\\Python\\Python310\\site-packages\\IPython\\core\\ultratb.py\", line 1428, in structured_traceback\n",
      "    return FormattedTB.structured_traceback(\n",
      "  File \"C:\\Users\\ngden\\AppData\\Roaming\\Python\\Python310\\site-packages\\IPython\\core\\ultratb.py\", line 1319, in structured_traceback\n",
      "    return VerboseTB.structured_traceback(\n",
      "  File \"C:\\Users\\ngden\\AppData\\Roaming\\Python\\Python310\\site-packages\\IPython\\core\\ultratb.py\", line 1172, in structured_traceback\n",
      "    formatted_exception = self.format_exception_as_a_whole(etype, evalue, etb, number_of_lines_of_context,\n",
      "  File \"C:\\Users\\ngden\\AppData\\Roaming\\Python\\Python310\\site-packages\\IPython\\core\\ultratb.py\", line 1087, in format_exception_as_a_whole\n",
      "    frames.append(self.format_record(record))\n",
      "  File \"C:\\Users\\ngden\\AppData\\Roaming\\Python\\Python310\\site-packages\\IPython\\core\\ultratb.py\", line 969, in format_record\n",
      "    frame_info.lines, Colors, self.has_colors, lvals\n",
      "  File \"C:\\Users\\ngden\\AppData\\Roaming\\Python\\Python310\\site-packages\\IPython\\core\\ultratb.py\", line 792, in lines\n",
      "    return self._sd.lines\n",
      "  File \"C:\\Users\\ngden\\AppData\\Roaming\\Python\\Python310\\site-packages\\stack_data\\utils.py\", line 144, in cached_property_wrapper\n",
      "    value = obj.__dict__[self.func.__name__] = self.func(obj)\n",
      "  File \"C:\\Users\\ngden\\AppData\\Roaming\\Python\\Python310\\site-packages\\stack_data\\core.py\", line 734, in lines\n",
      "    pieces = self.included_pieces\n",
      "  File \"C:\\Users\\ngden\\AppData\\Roaming\\Python\\Python310\\site-packages\\stack_data\\utils.py\", line 144, in cached_property_wrapper\n",
      "    value = obj.__dict__[self.func.__name__] = self.func(obj)\n",
      "  File \"C:\\Users\\ngden\\AppData\\Roaming\\Python\\Python310\\site-packages\\stack_data\\core.py\", line 677, in included_pieces\n",
      "    scope_pieces = self.scope_pieces\n",
      "  File \"C:\\Users\\ngden\\AppData\\Roaming\\Python\\Python310\\site-packages\\stack_data\\utils.py\", line 144, in cached_property_wrapper\n",
      "    value = obj.__dict__[self.func.__name__] = self.func(obj)\n",
      "  File \"C:\\Users\\ngden\\AppData\\Roaming\\Python\\Python310\\site-packages\\stack_data\\core.py\", line 614, in scope_pieces\n",
      "    scope_start, scope_end = self.source.line_range(self.scope)\n",
      "  File \"C:\\Users\\ngden\\AppData\\Roaming\\Python\\Python310\\site-packages\\stack_data\\core.py\", line 178, in line_range\n",
      "    return line_range(self.asttext(), node)\n",
      "AttributeError: 'Source' object has no attribute 'asttext'\n"
     ]
    }
   ],
   "source": [
    "predictions = model.predict(test, verbose=0)\n",
    "# predictions = predictions.reshape(1,-1)[0]\n",
    "# lst = np.argmax(predictions, axis= 1)\n",
    "lst = (predictions > 0.5).astype(int)\n",
    "\n",
    "print(classification_report(test.classes, lst, target_names = test.class_indices))"
   ]
  },
  {
   "cell_type": "markdown",
   "metadata": {},
   "source": [
    "<h3>Confusion matrix</h3>"
   ]
  },
  {
   "cell_type": "code",
   "execution_count": 18,
   "metadata": {},
   "outputs": [
    {
     "name": "stdout",
     "output_type": "stream",
     "text": [
      "Unexpected exception formatting exception. Falling back to standard exception\n"
     ]
    },
    {
     "name": "stderr",
     "output_type": "stream",
     "text": [
      "Traceback (most recent call last):\n",
      "  File \"C:\\Users\\ngden\\AppData\\Roaming\\Python\\Python310\\site-packages\\IPython\\core\\interactiveshell.py\", line 3508, in run_code\n",
      "    exec(code_obj, self.user_global_ns, self.user_ns)\n",
      "  File \"C:\\Users\\ngden\\AppData\\Local\\Temp\\ipykernel_728\\2610218718.py\", line 1, in <module>\n",
      "    result = confusion_matrix(test.classes, lst)\n",
      "NameError: name 'lst' is not defined\n",
      "\n",
      "During handling of the above exception, another exception occurred:\n",
      "\n",
      "Traceback (most recent call last):\n",
      "  File \"C:\\Users\\ngden\\AppData\\Roaming\\Python\\Python310\\site-packages\\IPython\\core\\interactiveshell.py\", line 2105, in showtraceback\n",
      "    stb = self.InteractiveTB.structured_traceback(\n",
      "  File \"C:\\Users\\ngden\\AppData\\Roaming\\Python\\Python310\\site-packages\\IPython\\core\\ultratb.py\", line 1428, in structured_traceback\n",
      "    return FormattedTB.structured_traceback(\n",
      "  File \"C:\\Users\\ngden\\AppData\\Roaming\\Python\\Python310\\site-packages\\IPython\\core\\ultratb.py\", line 1319, in structured_traceback\n",
      "    return VerboseTB.structured_traceback(\n",
      "  File \"C:\\Users\\ngden\\AppData\\Roaming\\Python\\Python310\\site-packages\\IPython\\core\\ultratb.py\", line 1172, in structured_traceback\n",
      "    formatted_exception = self.format_exception_as_a_whole(etype, evalue, etb, number_of_lines_of_context,\n",
      "  File \"C:\\Users\\ngden\\AppData\\Roaming\\Python\\Python310\\site-packages\\IPython\\core\\ultratb.py\", line 1087, in format_exception_as_a_whole\n",
      "    frames.append(self.format_record(record))\n",
      "  File \"C:\\Users\\ngden\\AppData\\Roaming\\Python\\Python310\\site-packages\\IPython\\core\\ultratb.py\", line 969, in format_record\n",
      "    frame_info.lines, Colors, self.has_colors, lvals\n",
      "  File \"C:\\Users\\ngden\\AppData\\Roaming\\Python\\Python310\\site-packages\\IPython\\core\\ultratb.py\", line 792, in lines\n",
      "    return self._sd.lines\n",
      "  File \"C:\\Users\\ngden\\AppData\\Roaming\\Python\\Python310\\site-packages\\stack_data\\utils.py\", line 144, in cached_property_wrapper\n",
      "    value = obj.__dict__[self.func.__name__] = self.func(obj)\n",
      "  File \"C:\\Users\\ngden\\AppData\\Roaming\\Python\\Python310\\site-packages\\stack_data\\core.py\", line 734, in lines\n",
      "    pieces = self.included_pieces\n",
      "  File \"C:\\Users\\ngden\\AppData\\Roaming\\Python\\Python310\\site-packages\\stack_data\\utils.py\", line 144, in cached_property_wrapper\n",
      "    value = obj.__dict__[self.func.__name__] = self.func(obj)\n",
      "  File \"C:\\Users\\ngden\\AppData\\Roaming\\Python\\Python310\\site-packages\\stack_data\\core.py\", line 677, in included_pieces\n",
      "    scope_pieces = self.scope_pieces\n",
      "  File \"C:\\Users\\ngden\\AppData\\Roaming\\Python\\Python310\\site-packages\\stack_data\\utils.py\", line 144, in cached_property_wrapper\n",
      "    value = obj.__dict__[self.func.__name__] = self.func(obj)\n",
      "  File \"C:\\Users\\ngden\\AppData\\Roaming\\Python\\Python310\\site-packages\\stack_data\\core.py\", line 614, in scope_pieces\n",
      "    scope_start, scope_end = self.source.line_range(self.scope)\n",
      "  File \"C:\\Users\\ngden\\AppData\\Roaming\\Python\\Python310\\site-packages\\stack_data\\core.py\", line 178, in line_range\n",
      "    return line_range(self.asttext(), node)\n",
      "AttributeError: 'Source' object has no attribute 'asttext'\n"
     ]
    }
   ],
   "source": [
    "result = confusion_matrix(test.classes, lst)\n",
    "print(result)\n",
    "\n",
    "def plot_confusion_matrix(result, classes, cmap=plt.cm.Blues):\n",
    "    plt.subplots(figsize=(7, 7))\n",
    "    plt.imshow(result, interpolation='nearest', cmap=cmap)\n",
    "    plt.title('Confusion matrix')\n",
    "    plt.colorbar()\n",
    "    tick_marks = np.arange(len(classes))\n",
    "    plt.xticks(tick_marks, classes, rotation = 90)\n",
    "    plt.yticks(tick_marks, classes)\n",
    "    plt.ylabel('True label')\n",
    "    plt.xlabel('Predicted label')\n",
    "   \n",
    "\n",
    "    thresh = result.max() / 2.\n",
    "    for i, j in itertools.product(range(result.shape[0]), range(result.shape[1])):\n",
    "        plt.text(j, i, result[i, j],\n",
    "            horizontalalignment=\"center\",\n",
    "            color = \"white\" if result[i, j] > thresh else \"black\")\n",
    "        \n",
    "    #current matplotlib version will cut off top and bottom of the matrix, \n",
    "    #hence the manual workaround - remove if matplotlib version does not cut off\n",
    "    b, t = plt.ylim() # discover bottom and top values\n",
    "    b += 0.5 # Add 0.5 to bottom\n",
    "    t -= 0.5 # Subtract 0.5 from top\n",
    "    plt.ylim(b, t) # update ylim(bottom, top) values\n",
    "    plt.show()\n",
    "    \n",
    "plot_confusion_matrix(result, list(test.class_indices.keys()))"
   ]
  },
  {
   "cell_type": "markdown",
   "metadata": {},
   "source": [
    "<h3>Save the model</h3>"
   ]
  },
  {
   "cell_type": "code",
   "execution_count": 19,
   "metadata": {},
   "outputs": [],
   "source": [
    "#change the directory back to initial path (Image Classification folder)\n",
    "os.chdir(\"../..\")\n",
    "# os.listdir()\n",
    "\n",
    "#save the model\n",
    "model.save(\"Models/VGG19/VGG19_covid_classification_finetuned.h5\")"
   ]
  }
 ],
 "metadata": {
  "kernelspec": {
   "display_name": "Python 3 (ipykernel)",
   "language": "python",
   "name": "python3"
  },
  "language_info": {
   "codemirror_mode": {
    "name": "ipython",
    "version": 3
   },
   "file_extension": ".py",
   "mimetype": "text/x-python",
   "name": "python",
   "nbconvert_exporter": "python",
   "pygments_lexer": "ipython3",
   "version": "3.10.9"
  }
 },
 "nbformat": 4,
 "nbformat_minor": 4
}
